Workbook

Sheet Season Totals
B1: W | C1: L | D1: T | E1: W% | F1: PA | G1: H | H1: K | I1: BB | J1: RBI | K1: AVG | L1: K% | M1: OBP | N1: B-SCR | O1: B-Rank | P1: IP | Q1: K | R1: BB | S1: HA | T1: RA | U1: ERA | V1: WHIP | W1: K:BB | X1: P-SCR | Y1: B-Rank
A2: matt | B2: 3 | C2: 3 | D2: 2 | E2: =(B2+(D2*0.5))/(B2+C2+D2) -> 0.5 | F2: =sum(vlookup($A2,'G1'!$A$12:$J$19,2,false),vlookup($A2,'G2'!$A$12:$K$19,2,false),vlookup($A2,'G3'!$A$13:$K$21,2,false),vlookup($A2,'G4'!$A$12:$J$19,2,false),vlookup($A2,'G5'!$A$12:$K$19,2,false),vlookup($A2,'G6'!$A$12:$J$19,2,false),vlookup($A2,'G7'!$A$12:$K$19,2,false),vlookup($A2,'G8'!$A$12:$K$19,2,false)) -> 61 | G2: =sum(vlookup($A2,'G1'!$A$12:$J$19,7,false), vlookup($A2,'G2'!$A$12:$K$19,7,false),vlookup($A2,'G3'!$A$12:$K$21,7,false),vlookup($A2,'G4'!$A$12:$J$19,7,false),vlookup($A2,'G5'!$A$12:$K$19,7,false),vlookup($A2,'G6'!$A$12:$K$19,7,false), vlookup($A2,'G7'!$A$12:$K$19,7,false), vlookup($A2,'G8'!$A$12:$K$19,7,false)) -> 13 | H2: =sum(vlookup($A2,'G1'!$A$12:$J$19,3,false), vlookup($A2,'G2'!$A$12:$K$19,3,false),vlookup($A2,'G3'!$A$12:$K$21,3,false),vlookup($A2,'G4'!$A$12:$J$19,3,false),vlookup($A2,'G5'!$A$12:$K$19,3,false),vlookup($A2,'G6'!$A$12:$K$19,3,false), vlookup($A2,'G7'!$A$12:$K$19,3,false), vlookup($A2,'G8'!$A$12:$K$19,3,false)) -> 14 | I2: =sum(vlookup($A2,'G1'!$A$12:$J$19,4,false),vlookup($A2,'G2'!$A$12:$K$19,4,false),vlookup($A2,'G3'!$A$12:$K$21,4,false),vlookup($A2,'G4'!$A$12:$J$19,4,false),vlookup($A2,'G5'!$A$12:$K$19,4,false),vlookup($A2,'G6'!$A$12:$K$19,4,false), vlookup($A2,'G7'!$A$12:$K$19,4,false), vlookup($A2,'G8'!$A$12:$K$19,4,false)) -> 12 | J2: =sum(vlookup($A2,'G1'!$A$12:$J$19,6,false),vlookup($A2,'G2'!$A$12:$K$19,6,false),vlookup($A2,'G3'!$A$12:$K$21,6,false),vlookup($A2,'G4'!$A$12:$J$19,6,false),vlookup($A2,'G5'!$A$12:$K$19,6,false),vlookup($A2,'G6'!$A$12:$K$19,6,false), vlookup($A2,'G7'!$A$12:$K$19,6,false), vlookup($A2,'G8'!$A$12:$K$19,6,false)) -> 4 | K2: =G2/(F2-I2) -> 0.26530612 | L2: =H2/F2 -> 0.2295082 | M2: =(G2+I2)/F2 -> 0.40983607 | N2: {=SUMPRODUCT(G2:J2/sum($B2:$C2),$G$10:$J$10)+FLOOR((K2-$K$10)/0.5,1)+FLOOR((L2-$L$10)/0.5,1)+FLOOR((M2/$M$10)/0.75,1)} -> 4.25 | O2: =RANK(N2,$N$2:$N$9) -> 2 | P2: =sum(vlookup($A2,'G1'!$A$2:$J$9,2,false), vlookup($A2,'G2'!$A$2:$J$9,2,false), vlookup($A2,'G3'!$A$2:$J$10,2,false), vlookup($A2,'G4'!$A$2:$J$11,2,false), vlookup($A2,'G5'!$A$2:$J$11,2,false),vlookup($A2,'G6'!$A$2:$J$12,2,false), vlookup($A2,'G7'!$A$2:$J$10,2,false), vlookup($A2,'G8'!$A$2:$K$9,2,false)) -> 17 | Q2: =sum(vlookup($A2,'G1'!$A$2:$J$9,3,false), vlookup($A2,'G2'!$A$2:$J$9,3,false), vlookup($A2,'G3'!$A$2:$J$10,3,false), vlookup($A2,'G4'!$A$2:$J$9,3,false), vlookup($A2,'G5'!$A$2:$J$9,3,false),vlookup($A2,'G6'!$A$2:$J$9,3,false), vlookup($A2,'G7'!$A$2:$J$9,3,false), vlookup($A2,'G8'!$A$2:$K$9,3,false)) -> 15 | R2: =sum(vlookup($A2,'G1'!$A$2:$J$9,4,false), vlookup($A2,'G2'!$A$2:$J$9,4,false), vlookup($A2,'G3'!$A$2:$J$10,4,false), vlookup($A2,'G4'!$A$2:$J$9,4,false), vlookup($A2,'G5'!$A$2:$J$9,4,false),vlookup($A2,'G6'!$A$2:$J$9,4,false), vlookup($A2,'G7'!$A$2:$J$9,4,false),vlookup($A2,'G8'!$A$2:$K$9,4,false)) -> 7 | S2: =sum(vlookup($A2,'G1'!$A$2:$J$9,6,false), vlookup($A2,'G2'!$A$2:$J$9,6,false), vlookup($A2,'G3'!$A$2:$J$10,6,false), vlookup($A2,'G4'!$A$2:$J$9,6,false), vlookup($A2,'G5'!$A$2:$J$9,6,false),vlookup($A2,'G6'!$A$2:$J$9,6,false), vlookup($A2,'G7'!$A$2:$J$9,6,false), vlookup($A2,'G8'!$A$2:$K$9,6,false)) -> 12 | T2: =sum(vlookup($A2,'G1'!$A$2:$J$9,5,false), vlookup($A2,'G2'!$A$2:$J$9,5,false), vlookup($A2,'G3'!$A$2:$J$10,5,false), vlookup($A2,'G4'!$A$2:$J$9,5,false), vlookup($A2,'G5'!$A$2:$J$9,5,false),vlookup($A2,'G6'!$A$2:$J$9,5,false), vlookup($A2,'G7'!$A$2:$J$9,5,false), vlookup($A2,'G8'!$A$2:$K$9,5,false)) -> 3 | U2: =(9*T2)/P2 -> 1.5882353 | V2: =(R2+S2)/P2 -> 1.1176471 | W2: =Q2/R2 -> 2.1428571 | X2: {=SUMPRODUCT(Q2:T2/P2,$Q$10:$T$10)+FLOOR((U2-$U$10)/-1,1)+FLOOR((V2-$V$10)/-0.5,1)+floor((W2-$W$10)/0.5,1)} -> 2.5882353 | Y2: =RANK(X2,$X$2:$X$9) -> 3
A3: Chuck | B3: 4 | C3: 2 | D3: 2 | E3: =(B3+(D3*0.5))/(B3+C3+D3) -> 0.625 | F3: =sum(vlookup($A3,'G1'!$A$12:$J$19,2,false),vlookup($A3,'G2'!$A$12:$K$19,2,false),vlookup($A3,'G3'!$A$13:$K$21,2,false),vlookup($A3,'G4'!$A$12:$J$19,2,false),vlookup($A3,'G5'!$A$12:$K$19,2,false),vlookup($A3,'G6'!$A$12:$J$19,2,false),vlookup($A3,'G7'!$A$12:$K$19,2,false),vlookup($A3,'G8'!$A$12:$K$19,2,false)) -> 57 | G3: =sum(vlookup($A3,'G1'!$A$12:$J$19,7,false), vlookup($A3,'G2'!$A$12:$K$19,7,false),vlookup($A3,'G3'!$A$12:$K$21,7,false),vlookup($A3,'G4'!$A$12:$J$19,7,false),vlookup($A3,'G5'!$A$12:$K$19,7,false),vlookup($A3,'G6'!$A$12:$K$19,7,false), vlookup($A3,'G7'!$A$12:$K$19,7,false), vlookup($A3,'G8'!$A$12:$K$19,7,false)) -> 17 | H3: =sum(vlookup($A3,'G1'!$A$12:$J$19,3,false), vlookup($A3,'G2'!$A$12:$K$19,3,false),vlookup($A3,'G3'!$A$12:$K$21,3,false),vlookup($A3,'G4'!$A$12:$J$19,3,false),vlookup($A3,'G5'!$A$12:$K$19,3,false),vlookup($A3,'G6'!$A$12:$K$19,3,false), vlookup($A3,'G7'!$A$12:$K$19,3,false), vlookup($A3,'G8'!$A$12:$K$19,3,false)) -> 11 | I3: =sum(vlookup($A3,'G1'!$A$12:$J$19,4,false),vlookup($A3,'G2'!$A$12:$K$19,4,false),vlookup($A3,'G3'!$A$12:$K$21,4,false),vlookup($A3,'G4'!$A$12:$J$19,4,false),vlookup($A3,'G5'!$A$12:$K$19,4,false),vlookup($A3,'G6'!$A$12:$K$19,4,false), vlookup($A3,'G7'!$A$12:$K$19,4,false), vlookup($A3,'G8'!$A$12:$K$19,4,false)) -> 6 | J3: =sum(vlookup($A3,'G1'!$A$12:$J$19,6,false),vlookup($A3,'G2'!$A$12:$K$19,6,false),vlookup($A3,'G3'!$A$12:$K$21,6,false),vlookup($A3,'G4'!$A$12:$J$19,6,false),vlookup($A3,'G5'!$A$12:$K$19,6,false),vlookup($A3,'G6'!$A$12:$K$19,6,false), vlookup($A3,'G7'!$A$12:$K$19,6,false), vlookup($A3,'G8'!$A$12:$K$19,6,false)) -> 1 | K3: =G3/(F3-I3) -> 0.33333333 | L3: =H3/F3 -> 0.19298246 | M3: =(G3+I3)/F3 -> 0.40350877 | N3: {=SUMPRODUCT(G3:J3/sum($B3:$C3),$G$10:$J$10)+FLOOR((K3-$K$10)/0.5,1)+FLOOR((L3-$L$10)/0.5,1)+FLOOR((M3/$M$10)/0.75,1)} -> 3.75 | O3: =RANK(N3,$N$2:$N$9) -> 4 | P3: =sum(vlookup($A3,'G1'!$A$2:$J$9,2,false), vlookup($A3,'G2'!$A$2:$J$9,2,false), vlookup($A3,'G3'!$A$2:$J$10,2,false), vlookup($A3,'G4'!$A$2:$J$11,2,false), vlookup($A3,'G5'!$A$2:$J$11,2,false),vlookup($A3,'G6'!$A$2:$J$12,2,false), vlookup($A3,'G7'!$A$2:$J$10,2,false), vlookup($A3,'G8'!$A$2:$K$9,2,false)) -> 14 | Q3: =sum(vlookup($A3,'G1'!$A$2:$J$9,3,false), vlookup($A3,'G2'!$A$2:$J$9,3,false), vlookup($A3,'G3'!$A$2:$J$10,3,false), vlookup($A3,'G4'!$A$2:$J$9,3,false), vlookup($A3,'G5'!$A$2:$J$9,3,false),vlookup($A3,'G6'!$A$2:$J$9,3,false), vlookup($A3,'G7'!$A$2:$J$9,3,false), vlookup($A3,'G8'!$A$2:$K$9,3,false)) -> 22 | R3: =sum(vlookup($A3,'G1'!$A$2:$J$9,4,false), vlookup($A3,'G2'!$A$2:$J$9,4,false), vlookup($A3,'G3'!$A$2:$J$10,4,false), vlookup($A3,'G4'!$A$2:$J$9,4,false), vlookup($A3,'G5'!$A$2:$J$9,4,false),vlookup($A3,'G6'!$A$2:$J$9,4,false), vlookup($A3,'G7'!$A$2:$J$9,4,false),vlookup($A3,'G8'!$A$2:$K$9,4,false)) -> 11 | S3: =sum(vlookup($A3,'G1'!$A$2:$J$9,6,false), vlookup($A3,'G2'!$A$2:$J$9,6,false), vlookup($A3,'G3'!$A$2:$J$10,6,false), vlookup($A3,'G4'!$A$2:$J$9,6,false), vlookup($A3,'G5'!$A$2:$J$9,6,false),vlookup($A3,'G6'!$A$2:$J$9,6,false), vlookup($A3,'G7'!$A$2:$J$9,6,false), vlookup($A3,'G8'!$A$2:$K$9,6,false)) -> 7 | T3: =sum(vlookup($A3,'G1'!$A$2:$J$9,5,false), vlookup($A3,'G2'!$A$2:$J$9,5,false), vlookup($A3,'G3'!$A$2:$J$10,5,false), vlookup($A3,'G4'!$A$2:$J$9,5,false), vlookup($A3,'G5'!$A$2:$J$9,5,false),vlookup($A3,'G6'!$A$2:$J$9,5,false), vlookup($A3,'G7'!$A$2:$J$9,5,false), vlookup($A3,'G8'!$A$2:$K$9,5,false)) -> 2 | U3: =(9*T3)/P3 -> 1.2857143 | V3: =(R3+S3)/P3 -> 1.2857143 | W3: =Q3/R3 -> 2 | X3: {=SUMPRODUCT(Q3:T3/P3,$Q$10:$T$10)+FLOOR((U3-$U$10)/-1,1)+FLOOR((V3-$V$10)/-0.5,1)+floor((W3-$W$10)/0.5,1)} -> 3.0357143 | Y3: =RANK(X3,$X$2:$X$9) -> 2
A4: Mason | B4: 1 | C4: 2 | D4: 2 | E4: =(B4+(D4*0.5))/(B4+C4+D4) -> 0.4 | F4: =sum(vlookup($A4,'G1'!$A$12:$J$19,2,false),vlookup($A4,'G2'!$A$12:$K$19,2,false),vlookup($A4,'G3'!$A$13:$K$21,2,false),vlookup($A4,'G4'!$A$12:$J$19,2,false),vlookup($A4,'G5'!$A$12:$K$19,2,false),vlookup($A4,'G6'!$A$12:$J$19,2,false),vlookup($A4,'G7'!$A$12:$K$19,2,false),vlookup($A4,'G8'!$A$12:$K$19,2,false)) -> 34 | G4: =sum(vlookup($A4,'G1'!$A$12:$J$19,7,false), vlookup($A4,'G2'!$A$12:$K$19,7,false),vlookup($A4,'G3'!$A$12:$K$21,7,false),vlookup($A4,'G4'!$A$12:$J$19,7,false),vlookup($A4,'G5'!$A$12:$K$19,7,false),vlookup($A4,'G6'!$A$12:$K$19,7,false), vlookup($A4,'G7'!$A$12:$K$19,7,false), vlookup($A4,'G8'!$A$12:$K$19,7,false)) -> 5 | H4: =sum(vlookup($A4,'G1'!$A$12:$J$19,3,false), vlookup($A4,'G2'!$A$12:$K$19,3,false),vlookup($A4,'G3'!$A$12:$K$21,3,false),vlookup($A4,'G4'!$A$12:$J$19,3,false),vlookup($A4,'G5'!$A$12:$K$19,3,false),vlookup($A4,'G6'!$A$12:$K$19,3,false), vlookup($A4,'G7'!$A$12:$K$19,3,false), vlookup($A4,'G8'!$A$12:$K$19,3,false)) -> 9 | I4: =sum(vlookup($A4,'G1'!$A$12:$J$19,4,false),vlookup($A4,'G2'!$A$12:$K$19,4,false),vlookup($A4,'G3'!$A$12:$K$21,4,false),vlookup($A4,'G4'!$A$12:$J$19,4,false),vlookup($A4,'G5'!$A$12:$K$19,4,false),vlookup($A4,'G6'!$A$12:$K$19,4,false), vlookup($A4,'G7'!$A$12:$K$19,4,false), vlookup($A4,'G8'!$A$12:$K$19,4,false)) -> 4 | J4: =sum(vlookup($A4,'G1'!$A$12:$J$19,6,false),vlookup($A4,'G2'!$A$12:$K$19,6,false),vlookup($A4,'G3'!$A$12:$K$21,6,false),vlookup($A4,'G4'!$A$12:$J$19,6,false),vlookup($A4,'G5'!$A$12:$K$19,6,false),vlookup($A4,'G6'!$A$12:$K$19,6,false), vlookup($A4,'G7'!$A$12:$K$19,6,false), vlookup($A4,'G8'!$A$12:$K$19,6,false)) -> 3 | K4: =G4/(F4-I4) -> 0.16666667 | L4: =H4/F4 -> 0.26470588 | M4: =(G4+I4)/F4 -> 0.26470588 | N4: {=SUMPRODUCT(G4:J4/sum($B4:$C4),$G$10:$J$10)+FLOOR((K4-$K$10)/0.5,1)+FLOOR((L4-$L$10)/0.5,1)+FLOOR((M4/$M$10)/0.75,1)} -> 1.8333333 | O4: =RANK(N4,$N$2:$N$9) -> 7 | P4: =sum(vlookup($A4,'G1'!$A$2:$J$9,2,false), vlookup($A4,'G2'!$A$2:$J$9,2,false), vlookup($A4,'G3'!$A$2:$J$10,2,false), vlookup($A4,'G4'!$A$2:$J$11,2,false), vlookup($A4,'G5'!$A$2:$J$11,2,false),vlookup($A4,'G6'!$A$2:$J$12,2,false), vlookup($A4,'G7'!$A$2:$J$10,2,false), vlookup($A4,'G8'!$A$2:$K$9,2,false)) -> 7 | Q4: =sum(vlookup($A4,'G1'!$A$2:$J$9,3,false), vlookup($A4,'G2'!$A$2:$J$9,3,false), vlookup($A4,'G3'!$A$2:$J$10,3,false), vlookup($A4,'G4'!$A$2:$J$9,3,false), vlookup($A4,'G5'!$A$2:$J$9,3,false),vlookup($A4,'G6'!$A$2:$J$9,3,false), vlookup($A4,'G7'!$A$2:$J$9,3,false), vlookup($A4,'G8'!$A$2:$K$9,3,false)) -> 2 | R4: =sum(vlookup($A4,'G1'!$A$2:$J$9,4,false), vlookup($A4,'G2'!$A$2:$J$9,4,false), vlookup($A4,'G3'!$A$2:$J$10,4,false), vlookup($A4,'G4'!$A$2:$J$9,4,false), vlookup($A4,'G5'!$A$2:$J$9,4,false),vlookup($A4,'G6'!$A$2:$J$9,4,false), vlookup($A4,'G7'!$A$2:$J$9,4,false),vlookup($A4,'G8'!$A$2:$K$9,4,false)) -> 3 | S4: =sum(vlookup($A4,'G1'!$A$2:$J$9,6,false), vlookup($A4,'G2'!$A$2:$J$9,6,false), vlookup($A4,'G3'!$A$2:$J$10,6,false), vlookup($A4,'G4'!$A$2:$J$9,6,false), vlookup($A4,'G5'!$A$2:$J$9,6,false),vlookup($A4,'G6'!$A$2:$J$9,6,false), vlookup($A4,'G7'!$A$2:$J$9,6,false), vlookup($A4,'G8'!$A$2:$K$9,6,false)) -> 8 | T4: =sum(vlookup($A4,'G1'!$A$2:$J$9,5,false), vlookup($A4,'G2'!$A$2:$J$9,5,false), vlookup($A4,'G3'!$A$2:$J$10,5,false), vlookup($A4,'G4'!$A$2:$J$9,5,false), vlookup($A4,'G5'!$A$2:$J$9,5,false),vlookup($A4,'G6'!$A$2:$J$9,5,false), vlookup($A4,'G7'!$A$2:$J$9,5,false), vlookup($A4,'G8'!$A$2:$K$9,5,false)) -> 1 | U4: =(9*T4)/P4 -> 1.2857143 | V4: =(R4+S4)/P4 -> 1.5714286 | W4: =Q4/R4 -> 0.66666667 | X4: {=SUMPRODUCT(Q4:T4/P4,$Q$10:$T$10)+FLOOR((U4-$U$10)/-1,1)+FLOOR((V4-$V$10)/-0.5,1)+floor((W4-$W$10)/0.5,1)} -> -3 | Y4: =RANK(X4,$X$2:$X$9) -> 7
A5: Liam | B5: 1 | C5: 3 | D5: 1 | E5: =(B5+(D5*0.5))/(B5+C5+D5) -> 0.3 | F5: =sum(vlookup($A5,'G1'!$A$12:$J$19,2,false),vlookup($A5,'G2'!$A$12:$K$19,2,false),vlookup($A5,'G3'!$A$13:$K$21,2,false),vlookup($A5,'G4'!$A$12:$J$19,2,false),vlookup($A5,'G5'!$A$12:$K$19,2,false),vlookup($A5,'G6'!$A$12:$J$19,2,false),vlookup($A5,'G7'!$A$12:$K$19,2,false),vlookup($A5,'G8'!$A$12:$K$19,2,false)) -> 33 | G5: =sum(vlookup($A5,'G1'!$A$12:$J$19,7,false), vlookup($A5,'G2'!$A$12:$K$19,7,false),vlookup($A5,'G3'!$A$12:$K$21,7,false),vlookup($A5,'G4'!$A$12:$J$19,7,false),vlookup($A5,'G5'!$A$12:$K$19,7,false),vlookup($A5,'G6'!$A$12:$K$19,7,false), vlookup($A5,'G7'!$A$12:$K$19,7,false), vlookup($A5,'G8'!$A$12:$K$19,7,false)) -> 10 | H5: =sum(vlookup($A5,'G1'!$A$12:$J$19,3,false), vlookup($A5,'G2'!$A$12:$K$19,3,false),vlookup($A5,'G3'!$A$12:$K$21,3,false),vlookup($A5,'G4'!$A$12:$J$19,3,false),vlookup($A5,'G5'!$A$12:$K$19,3,false),vlookup($A5,'G6'!$A$12:$K$19,3,false), vlookup($A5,'G7'!$A$12:$K$19,3,false), vlookup($A5,'G8'!$A$12:$K$19,3,false)) -> 7 | I5: =sum(vlookup($A5,'G1'!$A$12:$J$19,4,false),vlookup($A5,'G2'!$A$12:$K$19,4,false),vlookup($A5,'G3'!$A$12:$K$21,4,false),vlookup($A5,'G4'!$A$12:$J$19,4,false),vlookup($A5,'G5'!$A$12:$K$19,4,false),vlookup($A5,'G6'!$A$12:$K$19,4,false), vlookup($A5,'G7'!$A$12:$K$19,4,false), vlookup($A5,'G8'!$A$12:$K$19,4,false)) -> 5 | J5: =sum(vlookup($A5,'G1'!$A$12:$J$19,6,false),vlookup($A5,'G2'!$A$12:$K$19,6,false),vlookup($A5,'G3'!$A$12:$K$21,6,false),vlookup($A5,'G4'!$A$12:$J$19,6,false),vlookup($A5,'G5'!$A$12:$K$19,6,false),vlookup($A5,'G6'!$A$12:$K$19,6,false), vlookup($A5,'G7'!$A$12:$K$19,6,false), vlookup($A5,'G8'!$A$12:$K$19,6,false)) -> 2 | K5: =G5/(F5-I5) -> 0.35714286 | L5: =H5/F5 -> 0.21212121 | M5: =(G5+I5)/F5 -> 0.45454545 | N5: {=SUMPRODUCT(G5:J5/sum($B5:$C5),$G$10:$J$10)+FLOOR((K5-$K$10)/0.5,1)+FLOOR((L5-$L$10)/0.5,1)+FLOOR((M5/$M$10)/0.75,1)} -> 4.25 | O5: =RANK(N5,$N$2:$N$9) -> 2 | P5: =sum(vlookup($A5,'G1'!$A$2:$J$9,2,false), vlookup($A5,'G2'!$A$2:$J$9,2,false), vlookup($A5,'G3'!$A$2:$J$10,2,false), vlookup($A5,'G4'!$A$2:$J$11,2,false), vlookup($A5,'G5'!$A$2:$J$11,2,false),vlookup($A5,'G6'!$A$2:$J$12,2,false), vlookup($A5,'G7'!$A$2:$J$10,2,false), vlookup($A5,'G8'!$A$2:$K$9,2,false)) -> 7 | Q5: =sum(vlookup($A5,'G1'!$A$2:$J$9,3,false), vlookup($A5,'G2'!$A$2:$J$9,3,false), vlookup($A5,'G3'!$A$2:$J$10,3,false), vlookup($A5,'G4'!$A$2:$J$9,3,false), vlookup($A5,'G5'!$A$2:$J$9,3,false),vlookup($A5,'G6'!$A$2:$J$9,3,false), vlookup($A5,'G7'!$A$2:$J$9,3,false), vlookup($A5,'G8'!$A$2:$K$9,3,false)) -> 4 | R5: =sum(vlookup($A5,'G1'!$A$2:$J$9,4,false), vlookup($A5,'G2'!$A$2:$J$9,4,false), vlookup($A5,'G3'!$A$2:$J$10,4,false), vlookup($A5,'G4'!$A$2:$J$9,4,false), vlookup($A5,'G5'!$A$2:$J$9,4,false),vlookup($A5,'G6'!$A$2:$J$9,4,false), vlookup($A5,'G7'!$A$2:$J$9,4,false),vlookup($A5,'G8'!$A$2:$K$9,4,false)) -> 2 | S5: =sum(vlookup($A5,'G1'!$A$2:$J$9,6,false), vlookup($A5,'G2'!$A$2:$J$9,6,false), vlookup($A5,'G3'!$A$2:$J$10,6,false), vlookup($A5,'G4'!$A$2:$J$9,6,false), vlookup($A5,'G5'!$A$2:$J$9,6,false),vlookup($A5,'G6'!$A$2:$J$9,6,false), vlookup($A5,'G7'!$A$2:$J$9,6,false), vlookup($A5,'G8'!$A$2:$K$9,6,false)) -> 9 | T5: =sum(vlookup($A5,'G1'!$A$2:$J$9,5,false), vlookup($A5,'G2'!$A$2:$J$9,5,false), vlookup($A5,'G3'!$A$2:$J$10,5,false), vlookup($A5,'G4'!$A$2:$J$9,5,false), vlookup($A5,'G5'!$A$2:$J$9,5,false),vlookup($A5,'G6'!$A$2:$J$9,5,false), vlookup($A5,'G7'!$A$2:$J$9,5,false), vlookup($A5,'G8'!$A$2:$K$9,5,false)) -> 2 | U5: =(9*T5)/P5 -> 2.5714286 | V5: =(R5+S5)/P5 -> 1.5714286 | W5: =Q5/R5 -> 2 | X5: {=SUMPRODUCT(Q5:T5/P5,$Q$10:$T$10)+FLOOR((U5-$U$10)/-1,1)+FLOOR((V5-$V$10)/-0.5,1)+floor((W5-$W$10)/0.5,1)} -> -1.7142857 | Y5: =RANK(X5,$X$2:$X$9) -> 4
A6: Christian | B6: 2 | C6: 3 | D6: 1 | E6: =(B6+(D6*0.5))/(B6+C6+D6) -> 0.41666667 | F6: =sum(vlookup($A6,'G1'!$A$12:$J$19,2,false),vlookup($A6,'G2'!$A$12:$K$19,2,false),vlookup($A6,'G3'!$A$13:$K$21,2,false),vlookup($A6,'G4'!$A$12:$J$19,2,false),vlookup($A6,'G5'!$A$12:$K$19,2,false),vlookup($A6,'G6'!$A$12:$J$19,2,false),vlookup($A6,'G7'!$A$12:$K$19,2,false),vlookup($A6,'G8'!$A$12:$K$19,2,false)) -> 41 | G6: =sum(vlookup($A6,'G1'!$A$12:$J$19,7,false), vlookup($A6,'G2'!$A$12:$K$19,7,false),vlookup($A6,'G3'!$A$12:$K$21,7,false),vlookup($A6,'G4'!$A$12:$J$19,7,false),vlookup($A6,'G5'!$A$12:$K$19,7,false),vlookup($A6,'G6'!$A$12:$K$19,7,false), vlookup($A6,'G7'!$A$12:$K$19,7,false), vlookup($A6,'G8'!$A$12:$K$19,7,false)) -> 4 | H6: =sum(vlookup($A6,'G1'!$A$12:$J$19,3,false), vlookup($A6,'G2'!$A$12:$K$19,3,false),vlookup($A6,'G3'!$A$12:$K$21,3,false),vlookup($A6,'G4'!$A$12:$J$19,3,false),vlookup($A6,'G5'!$A$12:$K$19,3,false),vlookup($A6,'G6'!$A$12:$K$19,3,false), vlookup($A6,'G7'!$A$12:$K$19,3,false), vlookup($A6,'G8'!$A$12:$K$19,3,false)) -> 16 | I6: =sum(vlookup($A6,'G1'!$A$12:$J$19,4,false),vlookup($A6,'G2'!$A$12:$K$19,4,false),vlookup($A6,'G3'!$A$12:$K$21,4,false),vlookup($A6,'G4'!$A$12:$J$19,4,false),vlookup($A6,'G5'!$A$12:$K$19,4,false),vlookup($A6,'G6'!$A$12:$K$19,4,false), vlookup($A6,'G7'!$A$12:$K$19,4,false), vlookup($A6,'G8'!$A$12:$K$19,4,false)) -> 9 | J6: =sum(vlookup($A6,'G1'!$A$12:$J$19,6,false),vlookup($A6,'G2'!$A$12:$K$19,6,false),vlookup($A6,'G3'!$A$12:$K$21,6,false),vlookup($A6,'G4'!$A$12:$J$19,6,false),vlookup($A6,'G5'!$A$12:$K$19,6,false),vlookup($A6,'G6'!$A$12:$K$19,6,false), vlookup($A6,'G7'!$A$12:$K$19,6,false), vlookup($A6,'G8'!$A$12:$K$19,6,false)) -> 0 | K6: =G6/(F6-I6) -> 0.125 | L6: =H6/F6 -> 0.3902439 | M6: =(G6+I6)/F6 -> 0.31707317 | N6: {=SUMPRODUCT(G6:J6/sum($B6:$C6),$G$10:$J$10)+FLOOR((K6-$K$10)/0.5,1)+FLOOR((L6-$L$10)/0.5,1)+FLOOR((M6/$M$10)/0.75,1)} -> -0.2 | O6: =RANK(N6,$N$2:$N$9) -> 8 | P6: =sum(vlookup($A6,'G1'!$A$2:$J$9,2,false), vlookup($A6,'G2'!$A$2:$J$9,2,false), vlookup($A6,'G3'!$A$2:$J$10,2,false), vlookup($A6,'G4'!$A$2:$J$11,2,false), vlookup($A6,'G5'!$A$2:$J$11,2,false),vlookup($A6,'G6'!$A$2:$J$12,2,false), vlookup($A6,'G7'!$A$2:$J$10,2,false), vlookup($A6,'G8'!$A$2:$K$9,2,false)) -> 10 | Q6: =sum(vlookup($A6,'G1'!$A$2:$J$9,3,false), vlookup($A6,'G2'!$A$2:$J$9,3,false), vlookup($A6,'G3'!$A$2:$J$10,3,false), vlookup($A6,'G4'!$A$2:$J$9,3,false), vlookup($A6,'G5'!$A$2:$J$9,3,false),vlookup($A6,'G6'!$A$2:$J$9,3,false), vlookup($A6,'G7'!$A$2:$J$9,3,false), vlookup($A6,'G8'!$A$2:$K$9,3,false)) -> 11 | R6: =sum(vlookup($A6,'G1'!$A$2:$J$9,4,false), vlookup($A6,'G2'!$A$2:$J$9,4,false), vlookup($A6,'G3'!$A$2:$J$10,4,false), vlookup($A6,'G4'!$A$2:$J$9,4,false), vlookup($A6,'G5'!$A$2:$J$9,4,false),vlookup($A6,'G6'!$A$2:$J$9,4,false), vlookup($A6,'G7'!$A$2:$J$9,4,false),vlookup($A6,'G8'!$A$2:$K$9,4,false)) -> 5 | S6: =sum(vlookup($A6,'G1'!$A$2:$J$9,6,false), vlookup($A6,'G2'!$A$2:$J$9,6,false), vlookup($A6,'G3'!$A$2:$J$10,6,false), vlookup($A6,'G4'!$A$2:$J$9,6,false), vlookup($A6,'G5'!$A$2:$J$9,6,false),vlookup($A6,'G6'!$A$2:$J$9,6,false), vlookup($A6,'G7'!$A$2:$J$9,6,false), vlookup($A6,'G8'!$A$2:$K$9,6,false)) -> 5 | T6: =sum(vlookup($A6,'G1'!$A$2:$J$9,5,false), vlookup($A6,'G2'!$A$2:$J$9,5,false), vlookup($A6,'G3'!$A$2:$J$10,5,false), vlookup($A6,'G4'!$A$2:$J$9,5,false), vlookup($A6,'G5'!$A$2:$J$9,5,false),vlookup($A6,'G6'!$A$2:$J$9,5,false), vlookup($A6,'G7'!$A$2:$J$9,5,false), vlookup($A6,'G8'!$A$2:$K$9,5,false)) -> 2 | U6: =(9*T6)/P6 -> 1.8 | V6: =(R6+S6)/P6 -> 1 | W6: =Q6/R6 -> 2.2 | X6: {=SUMPRODUCT(Q6:T6/P6,$Q$10:$T$10)+FLOOR((U6-$U$10)/-1,1)+FLOOR((V6-$V$10)/-0.5,1)+floor((W6-$W$10)/0.5,1)} -> 3.15 | Y6: =RANK(X6,$X$2:$X$9) -> 1
A7: Logan | B7: 2 | C7: 1 | D7: 1 | E7: =(B7+(D7*0.5))/(B7+C7+D7) -> 0.625 | F7: =sum(vlookup($A7,'G1'!$A$12:$J$19,2,false),vlookup($A7,'G2'!$A$12:$K$19,2,false),vlookup($A7,'G3'!$A$13:$K$21,2,false),vlookup($A7,'G4'!$A$12:$J$19,2,false),vlookup($A7,'G5'!$A$12:$K$19,2,false),vlookup($A7,'G6'!$A$12:$J$19,2,false),vlookup($A7,'G7'!$A$12:$K$19,2,false),vlookup($A7,'G8'!$A$12:$K$19,2,false)) -> 22 | G7: =sum(vlookup($A7,'G1'!$A$12:$J$19,7,false), vlookup($A7,'G2'!$A$12:$K$19,7,false),vlookup($A7,'G3'!$A$12:$K$21,7,false),vlookup($A7,'G4'!$A$12:$J$19,7,false),vlookup($A7,'G5'!$A$12:$K$19,7,false),vlookup($A7,'G6'!$A$12:$K$19,7,false), vlookup($A7,'G7'!$A$12:$K$19,7,false), vlookup($A7,'G8'!$A$12:$K$19,7,false)) -> 6 | H7: =sum(vlookup($A7,'G1'!$A$12:$J$19,3,false), vlookup($A7,'G2'!$A$12:$K$19,3,false),vlookup($A7,'G3'!$A$12:$K$21,3,false),vlookup($A7,'G4'!$A$12:$J$19,3,false),vlookup($A7,'G5'!$A$12:$K$19,3,false),vlookup($A7,'G6'!$A$12:$K$19,3,false), vlookup($A7,'G7'!$A$12:$K$19,3,false), vlookup($A7,'G8'!$A$12:$K$19,3,false)) -> 7 | I7: =sum(vlookup($A7,'G1'!$A$12:$J$19,4,false),vlookup($A7,'G2'!$A$12:$K$19,4,false),vlookup($A7,'G3'!$A$12:$K$21,4,false),vlookup($A7,'G4'!$A$12:$J$19,4,false),vlookup($A7,'G5'!$A$12:$K$19,4,false),vlookup($A7,'G6'!$A$12:$K$19,4,false), vlookup($A7,'G7'!$A$12:$K$19,4,false), vlookup($A7,'G8'!$A$12:$K$19,4,false)) -> 2 | J7: =sum(vlookup($A7,'G1'!$A$12:$J$19,6,false),vlookup($A7,'G2'!$A$12:$K$19,6,false),vlookup($A7,'G3'!$A$12:$K$21,6,false),vlookup($A7,'G4'!$A$12:$J$19,6,false),vlookup($A7,'G5'!$A$12:$K$19,6,false),vlookup($A7,'G6'!$A$12:$K$19,6,false), vlookup($A7,'G7'!$A$12:$K$19,6,false), vlookup($A7,'G8'!$A$12:$K$19,6,false)) -> 1 | K7: =G7/(F7-I7) -> 0.3 | L7: =H7/F7 -> 0.31818182 | M7: =(G7+I7)/F7 -> 0.36363636 | N7: {=SUMPRODUCT(G7:J7/sum($B7:$C7),$G$10:$J$10)+FLOOR((K7-$K$10)/0.5,1)+FLOOR((L7-$L$10)/0.5,1)+FLOOR((M7/$M$10)/0.75,1)} -> 3 | O7: =RANK(N7,$N$2:$N$9) -> 6 | P7: =sum(vlookup($A7,'G1'!$A$2:$J$9,2,false), vlookup($A7,'G2'!$A$2:$J$9,2,false), vlookup($A7,'G3'!$A$2:$J$10,2,false), vlookup($A7,'G4'!$A$2:$J$11,2,false), vlookup($A7,'G5'!$A$2:$J$11,2,false),vlookup($A7,'G6'!$A$2:$J$12,2,false), vlookup($A7,'G7'!$A$2:$J$10,2,false), vlookup($A7,'G8'!$A$2:$K$9,2,false)) -> 4 | Q7: =sum(vlookup($A7,'G1'!$A$2:$J$9,3,false), vlookup($A7,'G2'!$A$2:$J$9,3,false), vlookup($A7,'G3'!$A$2:$J$10,3,false), vlookup($A7,'G4'!$A$2:$J$9,3,false), vlookup($A7,'G5'!$A$2:$J$9,3,false),vlookup($A7,'G6'!$A$2:$J$9,3,false), vlookup($A7,'G7'!$A$2:$J$9,3,false), vlookup($A7,'G8'!$A$2:$K$9,3,false)) -> 7 | R7: =sum(vlookup($A7,'G1'!$A$2:$J$9,4,false), vlookup($A7,'G2'!$A$2:$J$9,4,false), vlookup($A7,'G3'!$A$2:$J$10,4,false), vlookup($A7,'G4'!$A$2:$J$9,4,false), vlookup($A7,'G5'!$A$2:$J$9,4,false),vlookup($A7,'G6'!$A$2:$J$9,4,false), vlookup($A7,'G7'!$A$2:$J$9,4,false),vlookup($A7,'G8'!$A$2:$K$9,4,false)) -> 3 | S7: =sum(vlookup($A7,'G1'!$A$2:$J$9,6,false), vlookup($A7,'G2'!$A$2:$J$9,6,false), vlookup($A7,'G3'!$A$2:$J$10,6,false), vlookup($A7,'G4'!$A$2:$J$9,6,false), vlookup($A7,'G5'!$A$2:$J$9,6,false),vlookup($A7,'G6'!$A$2:$J$9,6,false), vlookup($A7,'G7'!$A$2:$J$9,6,false), vlookup($A7,'G8'!$A$2:$K$9,6,false)) -> 6 | T7: =sum(vlookup($A7,'G1'!$A$2:$J$9,5,false), vlookup($A7,'G2'!$A$2:$J$9,5,false), vlookup($A7,'G3'!$A$2:$J$10,5,false), vlookup($A7,'G4'!$A$2:$J$9,5,false), vlookup($A7,'G5'!$A$2:$J$9,5,false),vlookup($A7,'G6'!$A$2:$J$9,5,false), vlookup($A7,'G7'!$A$2:$J$9,5,false), vlookup($A7,'G8'!$A$2:$K$9,5,false)) -> 2 | U7: =(9*T7)/P7 -> 4.5 | V7: =(R7+S7)/P7 -> 2.25 | W7: =Q7/R7 -> 2.3333333 | X7: {=SUMPRODUCT(Q7:T7/P7,$Q$10:$T$10)+FLOOR((U7-$U$10)/-1,1)+FLOOR((V7-$V$10)/-0.5,1)+floor((W7-$W$10)/0.5,1)} -> -2.125 | Y7: =RANK(X7,$X$2:$X$9) -> 5
A8: Stephan | B8: 3 | C8: 0 | D8: 2 | E8: =(B8+(D8*0.5))/(B8+C8+D8) -> 0.8 | F8: =sum(vlookup($A8,'G1'!$A$12:$J$19,2,false),vlookup($A8,'G2'!$A$12:$K$19,2,false),vlookup($A8,'G3'!$A$13:$K$21,2,false),vlookup($A8,'G4'!$A$12:$J$19,2,false),vlookup($A8,'G5'!$A$12:$K$19,2,false),vlookup($A8,'G6'!$A$12:$J$19,2,false),vlookup($A8,'G7'!$A$12:$K$19,2,false),vlookup($A8,'G8'!$A$12:$K$19,2,false)) -> 31 | G8: =sum(vlookup($A8,'G1'!$A$12:$J$19,7,false), vlookup($A8,'G2'!$A$12:$K$19,7,false),vlookup($A8,'G3'!$A$12:$K$21,7,false),vlookup($A8,'G4'!$A$12:$J$19,7,false),vlookup($A8,'G5'!$A$12:$K$19,7,false),vlookup($A8,'G6'!$A$12:$K$19,7,false), vlookup($A8,'G7'!$A$12:$K$19,7,false), vlookup($A8,'G8'!$A$12:$K$19,7,false)) -> 5 | H8: =sum(vlookup($A8,'G1'!$A$12:$J$19,3,false), vlookup($A8,'G2'!$A$12:$K$19,3,false),vlookup($A8,'G3'!$A$12:$K$21,3,false),vlookup($A8,'G4'!$A$12:$J$19,3,false),vlookup($A8,'G5'!$A$12:$K$19,3,false),vlookup($A8,'G6'!$A$12:$K$19,3,false), vlookup($A8,'G7'!$A$12:$K$19,3,false), vlookup($A8,'G8'!$A$12:$K$19,3,false)) -> 5 | I8: =sum(vlookup($A8,'G1'!$A$12:$J$19,4,false),vlookup($A8,'G2'!$A$12:$K$19,4,false),vlookup($A8,'G3'!$A$12:$K$21,4,false),vlookup($A8,'G4'!$A$12:$J$19,4,false),vlookup($A8,'G5'!$A$12:$K$19,4,false),vlookup($A8,'G6'!$A$12:$K$19,4,false), vlookup($A8,'G7'!$A$12:$K$19,4,false), vlookup($A8,'G8'!$A$12:$K$19,4,false)) -> 12 | J8: =sum(vlookup($A8,'G1'!$A$12:$J$19,6,false),vlookup($A8,'G2'!$A$12:$K$19,6,false),vlookup($A8,'G3'!$A$12:$K$21,6,false),vlookup($A8,'G4'!$A$12:$J$19,6,false),vlookup($A8,'G5'!$A$12:$K$19,6,false),vlookup($A8,'G6'!$A$12:$K$19,6,false), vlookup($A8,'G7'!$A$12:$K$19,6,false), vlookup($A8,'G8'!$A$12:$K$19,6,false)) -> 5 | K8: =G8/(F8-I8) -> 0.26315789 | L8: =H8/F8 -> 0.16129032 | M8: =(G8+I8)/F8 -> 0.5483871 | N8: {=SUMPRODUCT(G8:J8/sum($B8:$C8),$G$10:$J$10)+FLOOR((K8-$K$10)/0.5,1)+FLOOR((L8-$L$10)/0.5,1)+FLOOR((M8/$M$10)/0.75,1)} -> 8.1666667 | O8: =RANK(N8,$N$2:$N$9) -> 1 | P8: =sum(vlookup($A8,'G1'!$A$2:$J$9,2,false), vlookup($A8,'G2'!$A$2:$J$9,2,false), vlookup($A8,'G3'!$A$2:$J$10,2,false), vlookup($A8,'G4'!$A$2:$J$11,2,false), vlookup($A8,'G5'!$A$2:$J$11,2,false),vlookup($A8,'G6'!$A$2:$J$12,2,false), vlookup($A8,'G7'!$A$2:$J$10,2,false), vlookup($A8,'G8'!$A$2:$K$9,2,false)) -> 8 | Q8: =sum(vlookup($A8,'G1'!$A$2:$J$9,3,false), vlookup($A8,'G2'!$A$2:$J$9,3,false), vlookup($A8,'G3'!$A$2:$J$10,3,false), vlookup($A8,'G4'!$A$2:$J$9,3,false), vlookup($A8,'G5'!$A$2:$J$9,3,false),vlookup($A8,'G6'!$A$2:$J$9,3,false), vlookup($A8,'G7'!$A$2:$J$9,3,false), vlookup($A8,'G8'!$A$2:$K$9,3,false)) -> 7 | R8: =sum(vlookup($A8,'G1'!$A$2:$J$9,4,false), vlookup($A8,'G2'!$A$2:$J$9,4,false), vlookup($A8,'G3'!$A$2:$J$10,4,false), vlookup($A8,'G4'!$A$2:$J$9,4,false), vlookup($A8,'G5'!$A$2:$J$9,4,false),vlookup($A8,'G6'!$A$2:$J$9,4,false), vlookup($A8,'G7'!$A$2:$J$9,4,false),vlookup($A8,'G8'!$A$2:$K$9,4,false)) -> 7 | S8: =sum(vlookup($A8,'G1'!$A$2:$J$9,6,false), vlookup($A8,'G2'!$A$2:$J$9,6,false), vlookup($A8,'G3'!$A$2:$J$10,6,false), vlookup($A8,'G4'!$A$2:$J$9,6,false), vlookup($A8,'G5'!$A$2:$J$9,6,false),vlookup($A8,'G6'!$A$2:$J$9,6,false), vlookup($A8,'G7'!$A$2:$J$9,6,false), vlookup($A8,'G8'!$A$2:$K$9,6,false)) -> 6 | T8: =sum(vlookup($A8,'G1'!$A$2:$J$9,5,false), vlookup($A8,'G2'!$A$2:$J$9,5,false), vlookup($A8,'G3'!$A$2:$J$10,5,false), vlookup($A8,'G4'!$A$2:$J$9,5,false), vlookup($A8,'G5'!$A$2:$J$9,5,false),vlookup($A8,'G6'!$A$2:$J$9,5,false), vlookup($A8,'G7'!$A$2:$J$9,5,false), vlookup($A8,'G8'!$A$2:$K$9,5,false)) -> 2 | U8: =(9*T8)/P8 -> 2.25 | V8: =(R8+S8)/P8 -> 1.625 | W8: =Q8/R8 -> 1 | X8: {=SUMPRODUCT(Q8:T8/P8,$Q$10:$T$10)+FLOOR((U8-$U$10)/-1,1)+FLOOR((V8-$V$10)/-0.5,1)+floor((W8-$W$10)/0.5,1)} -> -2.8125 | Y8: =RANK(X8,$X$2:$X$9) -> 6
A9: Jackson | B9: 0 | C9: 1 | D9: 2 | E9: =(B9+(D9*0.5))/(B9+C9+D9) -> 0.33333333 | F9: =sum(vlookup($A9,'G1'!$A$12:$J$19,2,false),vlookup($A9,'G2'!$A$12:$K$19,2,false),vlookup($A9,'G3'!$A$13:$K$21,2,false),vlookup($A9,'G4'!$A$12:$J$19,2,false),vlookup($A9,'G5'!$A$12:$K$19,2,false),vlookup($A9,'G6'!$A$12:$J$19,2,false),vlookup($A9,'G7'!$A$12:$K$19,2,false),vlookup($A9,'G8'!$A$12:$K$19,2,false)) -> 13 | G9: =sum(vlookup($A9,'G1'!$A$12:$J$19,7,false), vlookup($A9,'G2'!$A$12:$K$19,7,false),vlookup($A9,'G3'!$A$12:$K$21,7,false),vlookup($A9,'G4'!$A$12:$J$19,7,false),vlookup($A9,'G5'!$A$12:$K$19,7,false),vlookup($A9,'G6'!$A$12:$K$19,7,false), vlookup($A9,'G7'!$A$12:$K$19,7,false), vlookup($A9,'G8'!$A$12:$K$19,7,false)) -> 2 | H9: =sum(vlookup($A9,'G1'!$A$12:$J$19,3,false), vlookup($A9,'G2'!$A$12:$K$19,3,false),vlookup($A9,'G3'!$A$12:$K$21,3,false),vlookup($A9,'G4'!$A$12:$J$19,3,false),vlookup($A9,'G5'!$A$12:$K$19,3,false),vlookup($A9,'G6'!$A$12:$K$19,3,false), vlookup($A9,'G7'!$A$12:$K$19,3,false), vlookup($A9,'G8'!$A$12:$K$19,3,false)) -> 3 | I9: =sum(vlookup($A9,'G1'!$A$12:$J$19,4,false),vlookup($A9,'G2'!$A$12:$K$19,4,false),vlookup($A9,'G3'!$A$12:$K$21,4,false),vlookup($A9,'G4'!$A$12:$J$19,4,false),vlookup($A9,'G5'!$A$12:$K$19,4,false),vlookup($A9,'G6'!$A$12:$K$19,4,false), vlookup($A9,'G7'!$A$12:$K$19,4,false), vlookup($A9,'G8'!$A$12:$K$19,4,false)) -> 2 | J9: =sum(vlookup($A9,'G1'!$A$12:$J$19,6,false),vlookup($A9,'G2'!$A$12:$K$19,6,false),vlookup($A9,'G3'!$A$12:$K$21,6,false),vlookup($A9,'G4'!$A$12:$J$19,6,false),vlookup($A9,'G5'!$A$12:$K$19,6,false),vlookup($A9,'G6'!$A$12:$K$19,6,false), vlookup($A9,'G7'!$A$12:$K$19,6,false), vlookup($A9,'G8'!$A$12:$K$19,6,false)) -> 1 | K9: =G9/(F9-I9) -> 0.18181818 | L9: =H9/F9 -> 0.23076923 | M9: =(G9+I9)/F9 -> 0.30769231 | N9: {=SUMPRODUCT(G9:J9/sum($B9:$C9),$G$10:$J$10)+FLOOR((K9-$K$10)/0.5,1)+FLOOR((L9-$L$10)/0.5,1)+FLOOR((M9/$M$10)/0.75,1)} -> 3 | O9: =RANK(N9,$N$2:$N$9) -> 5 | P9: =sum(vlookup($A9,'G1'!$A$2:$J$9,2,false), vlookup($A9,'G2'!$A$2:$J$9,2,false), vlookup($A9,'G3'!$A$2:$J$10,2,false), vlookup($A9,'G4'!$A$2:$J$11,2,false), vlookup($A9,'G5'!$A$2:$J$11,2,false),vlookup($A9,'G6'!$A$2:$J$12,2,false), vlookup($A9,'G7'!$A$2:$J$10,2,false), vlookup($A9,'G8'!$A$2:$K$9,2,false)) -> 4 | Q9: =sum(vlookup($A9,'G1'!$A$2:$J$9,3,false), vlookup($A9,'G2'!$A$2:$J$9,3,false), vlookup($A9,'G3'!$A$2:$J$10,3,false), vlookup($A9,'G4'!$A$2:$J$9,3,false), vlookup($A9,'G5'!$A$2:$J$9,3,false),vlookup($A9,'G6'!$A$2:$J$9,3,false), vlookup($A9,'G7'!$A$2:$J$9,3,false), vlookup($A9,'G8'!$A$2:$K$9,3,false)) -> 3 | R9: =sum(vlookup($A9,'G1'!$A$2:$J$9,4,false), vlookup($A9,'G2'!$A$2:$J$9,4,false), vlookup($A9,'G3'!$A$2:$J$10,4,false), vlookup($A9,'G4'!$A$2:$J$9,4,false), vlookup($A9,'G5'!$A$2:$J$9,4,false),vlookup($A9,'G6'!$A$2:$J$9,4,false), vlookup($A9,'G7'!$A$2:$J$9,4,false),vlookup($A9,'G8'!$A$2:$K$9,4,false)) -> 4 | S9: =sum(vlookup($A9,'G1'!$A$2:$J$9,6,false), vlookup($A9,'G2'!$A$2:$J$9,6,false), vlookup($A9,'G3'!$A$2:$J$10,6,false), vlookup($A9,'G4'!$A$2:$J$9,6,false), vlookup($A9,'G5'!$A$2:$J$9,6,false),vlookup($A9,'G6'!$A$2:$J$9,6,false), vlookup($A9,'G7'!$A$2:$J$9,6,false), vlookup($A9,'G8'!$A$2:$K$9,6,false)) -> 4 | T9: =sum(vlookup($A9,'G1'!$A$2:$J$9,5,false), vlookup($A9,'G2'!$A$2:$J$9,5,false), vlookup($A9,'G3'!$A$2:$J$10,5,false), vlookup($A9,'G4'!$A$2:$J$9,5,false), vlookup($A9,'G5'!$A$2:$J$9,5,false),vlookup($A9,'G6'!$A$2:$J$9,5,false), vlookup($A9,'G7'!$A$2:$J$9,5,false), vlookup($A9,'G8'!$A$2:$K$9,5,false)) -> 3 | U9: =(9*T9)/P9 -> 6.75 | V9: =(R9+S9)/P9 -> 2 | W9: =Q9/R9 -> 0.75 | X9: {=SUMPRODUCT(Q9:T9/P9,$Q$10:$T$10)+FLOOR((U9-$U$10)/-1,1)+FLOOR((V9-$V$10)/-0.5,1)+floor((W9-$W$10)/0.5,1)} -> -8.125 | Y9: =RANK(X9,$X$2:$X$9) -> 8
G10: 1.5 | H10: -1 | I10: 1 | J10: 2 | K10: =AVERAGE(K2:K9) -> 0.24905313 | L10: =AVERAGE(L2:L9) -> 0.24997538 | M10: =AVERAGE(M2:M9) -> 0.38367314 | Q10: 2 | R10: -0.5 | S10: -1 | T10: -1.5 | U10: =AVERAGE(U2:U9) -> 2.7538866 | V10: =AVERAGE(V2:V9) -> 1.5526523 | W10: =AVERAGE(W2:W9) -> 1.6366071
A12: Static Table
B13: W | C13: L | D13: T | E13: W% | F13: PA | G13: H | H13: K | I13: BB | J13: RBI | K13: AVG | L13: K% | M13: OBP | P13: IP | Q13: K | R13: BB | S13: HA | T13: RA | U13: ERA | V13: WHIP | W13: K:BB
A14: matt | B14: 3 | C14: 3 | D14: 2 | E14: 0.5 | F14: 61 | G14: 13 | H14: 14 | I14: 12 | J14: 4 | K14: =G14/(F14-I14) -> 0.26530612 | L14: =H14/F14 -> 0.2295082 | M14: =(G14+I14)/F14 -> 0.40983607 | P14: 17 | Q14: 15 | R14: 7 | S14: 12 | T14: 3 | U14: =(9*T14)/P14 -> 1.5882353 | V14: =(R14+S14)/P14 -> 1.1176471 | W14: =Q14/R14 -> 2.1428571
A15: Chuck | B15: 4 | C15: 2 | D15: 2 | E15: 0.625 | F15: 57 | G15: 17 | H15: 11 | I15: 6 | J15: 1 | K15: =G15/(F15-I15) -> 0.33333333 | L15: =H15/F15 -> 0.19298246 | M15: =(G15+I15)/F15 -> 0.40350877 | P15: 14 | Q15: 22 | R15: 11 | S15: 7 | T15: 2 | U15: =(9*T15)/P15 -> 1.2857143 | V15: =(R15+S15)/P15 -> 1.2857143 | W15: =Q15/R15 -> 2
A16: Mason | B16: 1 | C16: 2 | D16: 2 | E16: 0.4 | F16: 34 | G16: 5 | H16: 9 | I16: 4 | J16: 3 | K16: =G16/(F16-I16) -> 0.16666667 | L16: =H16/F16 -> 0.26470588 | M16: =(G16+I16)/F16 -> 0.26470588 | P16: 7 | Q16: 2 | R16: 3 | S16: 8 | T16: 1 | U16: =(9*T16)/P16 -> 1.2857143 | V16: =(R16+S16)/P16 -> 1.5714286 | W16: =Q16/R16 -> 0.66666667
A17: Liam | B17: 1 | C17: 3 | D17: 1 | E17: 0.3 | F17: 33 | G17: 10 | H17: 7 | I17: 5 | J17: 2 | K17: =G17/(F17-I17) -> 0.35714286 | L17: =H17/F17 -> 0.21212121 | M17: =(G17+I17)/F17 -> 0.45454545 | P17: 7 | Q17: 4 | R17: 2 | S17: 9 | T17: 2 | U17: =(9*T17)/P17 -> 2.5714286 | V17: =(R17+S17)/P17 -> 1.5714286 | W17: =Q17/R17 -> 2
A18: Christian | B18: 2 | C18: 3 | D18: 1 | E18: 0.417 | F18: 41 | G18: 4 | H18: 16 | I18: 9 | J18: 0 | K18: =G18/(F18-I18) -> 0.125 | L18: =H18/F18 -> 0.3902439 | M18: =(G18+I18)/F18 -> 0.31707317 | P18: 10 | Q18: 11 | R18: 5 | S18: 5 | T18: 2 | U18: =(9*T18)/P18 -> 1.8 | V18: =(R18+S18)/P18 -> 1 | W18: =Q18/R18 -> 2.2
A19: Logan | B19: 2 | C19: 1 | D19: 1 | E19: 0.625 | F19: 22 | G19: 6 | H19: 7 | I19: 2 | J19: 1 | K19: =G19/(F19-I19) -> 0.3 | L19: =H19/F19 -> 0.31818182 | M19: =(G19+I19)/F19 -> 0.36363636 | P19: 4 | Q19: 7 | R19: 3 | S19: 6 | T19: 2 | U19: =(9*T19)/P19 -> 4.5 | V19: =(R19+S19)/P19 -> 2.25 | W19: =Q19/R19 -> 2.3333333
A20: Stephan | B20: 3 | C20: 0 | D20: 2 | E20: 0.8 | F20: 31 | G20: 5 | H20: 5 | I20: 12 | J20: 5 | K20: =G20/(F20-I20) -> 0.26315789 | L20: =H20/F20 -> 0.16129032 | M20: =(G20+I20)/F20 -> 0.5483871 | P20: 8 | Q20: 7 | R20: 7 | S20: 6 | T20: 2 | U20: =(9*T20)/P20 -> 2.25 | V20: =(R20+S20)/P20 -> 1.625 | W20: =Q20/R20 -> 1
A21: Jackson | B21: 0 | C21: 1 | D21: 2 | E21: 0.33 | F21: 13 | G21: 2 | H21: 3 | I21: 2 | J21: 1 | K21: =G21/(F21-I21) -> 0.18181818 | L21: =H21/F21 -> 0.23076923 | M21: =(G21+I21)/F21 -> 0.30769231 | P21: 4 | Q21: 3 | R21: 4 | S21: 4 | T21: 3 | U21: =(9*T21)/P21 -> 6.75 | V21: =(R21+S21)/P21 -> 2 | W21: =Q21/R21 -> 0.75

Sheet Revised ST
A1: 44707 | B1: IP | C1: K | D1: BB | E1: RA | F1: HA | G1: 1A | H1: 2A | I1: 3A | J1: HRA | L1: ERA | M1: WHIP
A2: Matt | B2: 2 | C2: 4 | F2: =sum(G2:J2) -> 1 | G2: 1 | L2: =9*E2/B2 -> 0 | M2: =(D2+F2)/B2 -> 0.5
A3: Chuck | B3: 2 | C3: 2 | F3: =sum(G3:J3) -> 2 | G3: 1 | H3: 1 | L3: =9*E3/B3 -> 0 | M3: =(D3+F3)/B3 -> 1
A4: Liam | B4: 2 | D4: 1 | E4: 1 | F4: =sum(G4:J4) -> 4 | G4: 1 | H4: 3 | L4: =9*E4/B4 -> 4.5 | M4: =(D4+F4)/B4 -> 2.5
A5: Mason | B5: 1 | F5: =sum(G5:J5) -> 2 | G5: 1 | H5: 1 | L5: =9*E5/B5 -> 0 | M5: =(D5+F5)/B5 -> 2
A7: 44708 | B7: IP | C7: K | D7: BB | E7: RA | F7: HA | G7: 1A | H7: 2A | I7: 3A | J7: HRA | L7: ERA | M7: WHIP
A8: Chuck | B8: 2 | C8: 3 | F8: =sum(G8:J8) -> 2 | H8: 2 | L8: =9*E8/B8 -> 0 | M8: =(D8+F8)/B8 -> 1
A9: Christian | B9: 1 | C9: 2 | D9: 1 | F9: =sum(G9:J9) -> 2 | G9: 2 | L9: =9*E9/B9 -> 0 | M9: =(D9+F9)/B9 -> 3
A10: Logan | B10: 1 | C10: 3 | F10: =sum(G10:J10) -> 0 | L10: =9*E10/B10 -> 0 | M10: =(D10+F10)/B10 -> 0
A11: Matt | B11: 2 | C11: 3 | F11: =sum(G11:J11) -> 1 | H11: 1 | L11: =9*E11/B11 -> 0 | M11: =(D11+F11)/B11 -> 0.5
A13: 44711 | B13: IP | C13: K | D13: BB | E13: RA | F13: HA | G13: 1A | H13: 2A | I13: 3A | J13: HRA | L13: ERA | M13: WHIP
A14: Matt | B14: 2 | C14: 1 | F14: =sum(G14:J14) -> 5 | G14: 5 | L14: =9*E14/B14 -> 0 | M14: =(D14+F14)/B14 -> 2.5
A15: Chuck | B15: 1 | C15: 2 | D15: 2 | F15: =sum(G15:J15) -> 0 | L15: =9*E15/B15 -> 0 | M15: =(D15+F15)/B15 -> 2
A16: Liam | B16: 2 | C16: 1 | E16: 1 | F16: =sum(G16:J16) -> 2 | H16: 2 | L16: =9*E16/B16 -> 4.5 | M16: =(D16+F16)/B16 -> 1
A17: Christian | B17: 2 | C17: 2 | F17: =sum(G17:J17) -> 0 | L17: =9*E17/B17 -> 0 | M17: =(D17+F17)/B17 -> 0
A18: Logan | B18: 1 | C18: 2 | D18: 1 | E18: 2 | F18: =sum(G18:J18) -> 4 | G18: 4 | L18: =9*E18/B18 -> 18 | M18: =(D18+F18)/B18 -> 5
A19: Finn | B19: 2 | D19: 1 | F19: =sum(G19:J19) -> 2 | G19: 1 | H19: 1 | L19: =9*E19/B19 -> 0 | M19: =(D19+F19)/B19 -> 1.5
A21: 44715 | B21: IP | C21: K | D21: BB | E21: RA | F21: HA | G21: 1A | H21: 2A | I21: 3A | J21: HRA | L21: ERA | M21: WHIP
A22: Stephan | B22: 2 | C22: 1 | D22: 2 | F22: =sum(G22:J22) -> 2 | G22: 1 | H22: 1 | L22: =9*E22/B22 -> 0 | M22: =(D22+F22)/B22 -> 2
A23: Christian | B23: 2 | C23: 4 | E23: 1 | F23: =sum(G23:J23) -> 1 | J23: 1 | L23: =9*E23/B23 -> 4.5 | M23: =(D23+F23)/B23 -> 0.5
A24: Chuck | B24: 2 | C24: 5 | D24: 2 | F24: =sum(G24:J24) -> 0 | L24: =9*E24/B24 -> 0 | M24: =(D24+F24)/B24 -> 1
A25: Mason | B25: 2 | F25: =sum(G25:J25) -> 2 | G25: 1 | H25: 1 | L25: =9*E25/B25 -> 0 | M25: =(D25+F25)/B25 -> 1
A26: Liam | B26: 2 | C26: 3 | D26: 1 | F26: =sum(G26:J26) -> 1 | H26: 1 | L26: =9*E26/B26 -> 0 | M26: =(D26+F26)/B26 -> 1
A27: Matt | B27: 2 | C27: 1 | D27: 4 | E27: 3 | F27: =sum(G27:J27) -> 1 | J27: 1 | L27: =9*E27/B27 -> 13.5 | M27: =(D27+F27)/B27 -> 2.5
A29: 44728 | B29: IP | C29: K | D29: BB | E29: RA | F29: HA | G29: 1A | H29: 2A | I29: 3A | J29: HRA | L29: ERA | M29: WHIP
A30: Stephan | B30: 2 | C30: 2 | D30: 1 | F30: =sum(G30:J30) -> 1 | H30: 1 | L30: =9*E30/B30 -> 0 | M30: =(D30+F30)/B30 -> 1
A31: Chuck | B31: 2 | C31: 3 | F31: =sum(G31:J31) -> 1 | H31: 1 | L31: =9*E31/B31 -> 0 | M31: =(D31+F31)/B31 -> 0.5
A32: Logan | B32: 1 | C32: 2 | D32: 2 | F32: =sum(G32:J32) -> 0 | L32: =9*E32/B32 -> 0 | M32: =(D32+F32)/B32 -> 2
A33: Matt | B33: 3 | C33: 2 | D33: 1 | F33: =sum(G33:J33) -> 1 | H33: 1 | L33: =9*E33/B33 -> 0 | M33: =(D33+F33)/B33 -> 0.66666667
A34: Christian | B34: 3 | C34: 2 | D34: 2 | E34: 1 | F34: =sum(G34:J34) -> 2 | G34: 1 | H34: 1 | L34: =9*E34/B34 -> 3 | M34: =(D34+F34)/B34 -> 1.3333333
A36: 44729 | B36: IP | C36: K | D36: BB | E36: RA | F36: HA | G36: 1A | H36: 2A | I36: 3A | J36: HRA | L36: ERA | M36: WHIP
A37: Jackson | B37: 2 | C37: 2 | D37: 1 | F37: =SUM(G37:J37) -> 2 | G37: 2 | L37: =9*E37/B37 -> 0 | M37: =(D37+F37)/B37 -> 1.5
A38: Stephan | B38: 2 | C38: 1 | D38: 1 | E38: 2 | F38: =SUM(G38:J38) -> 3 | G38: 1 | H38: 2 | L38: =9*E38/B38 -> 9 | M38: =(D38+F38)/B38 -> 2
A39: Mason | B39: 2 | C39: 2 | D39: 3 | F39: =SUM(G39:J39) -> 2 | G39: 1 | H39: 1 | L39: =9*E39/B39 -> 0 | M39: =(D39+F39)/B39 -> 2.5
A40: Matt | B40: 3 | C40: 3 | F40: =SUM(G40:J40) -> 1 | H40: 1 | L40: =9*E40/B40 -> 0 | M40: =(D40+F40)/B40 -> 0.33333333
A41: Chuck | B41: 3 | C41: 4 | D41: 6 | E41: 2 | F41: =SUM(G41:J41) -> 0 | L41: =9*E41/B41 -> 6 | M41: =(D41+F41)/B41 -> 2
A43: 44730 | B43: IP | C43: K | D43: BB | E43: RA | F43: HA | G43: 1A | H43: 2A | I43: 3A | J43: HRA | L43: ERA | M43: WHIP
A44: Chuck | B44: 1 | D44: 1 | F44: =SUM(G44:J44) -> 0 | L44: =9*E44/B44 -> 0 | M44: =(D44+F44)/B44 -> 1
A45: Jackson | B45: 1 | D45: 3 | E45: 3 | F45: =SUM(G45:J45) -> 1 | H45: 1 | L45: =9*E45/B45 -> 27 | M45: =(D45+F45)/B45 -> 4
A46: Christian | B46: 1 | D46: 1 | F46: =SUM(G46:J46) -> 0 | L46: =9*E46/B46 -> 0 | M46: =(D46+F46)/B46 -> 1
...

Sheet G8
A1: 44731 | B1: IP | C1: K | D1: BB | E1: RA | F1: HA | G1: 1A | H1: 2A | I1: 3A | J1: HRA | L1: ERA | M1: WHIP
A2: Logan | B2: 1 | F2: =SUM(G2:J2) -> 2 | G2: 1 | H2: 1 | L2: =9*E2/B2 -> 0 | M2: =(D2+F2)/B2 -> 2
A3: Stephan | B3: 1 | C3: 2 | D3: 1 | F3: =SUM(G3:J3) -> 0 | L3: =9*E3/B3 -> 0 | M3: =(D3+F3)/B3 -> 1
A4: Matt | B4: 1 | C4: 1 | D4: 1 | F4: =SUM(G4:J4) -> 1 | H4: 1 | L4: =9*E4/B4 -> 0 | M4: =(D4+F4)/B4 -> 2
A5: Mason | B5: 1 | F5: =SUM(G5:J5) -> 0 | L5: =9*E5/B5 -> 0 | M5: =(D5+F5)/B5 -> 0
A6: Christian | B6: 1 | C6: 1 | D6: 1 | F6: =SUM(G6:J6) -> 0 | L6: =9*E6/B6 -> 0 | M6: =(D6+F6)/B6 -> 1
A7: Liam | B7: 1 | F7: =SUM(G7:J7) -> 2 | G7: 2 | L7: =9*E7/B7 -> 0 | M7: =(D7+F7)/B7 -> 2
A8: Chuck | B8: 1 | C8: 3 | F8: =SUM(G8:J8) -> 2 | G8: 2 | L8: =9*E8/B8 -> 0 | M8: =(D8+F8)/B8 -> 2
A9: Jackson | B9: 1 | C9: 1 | F9: 1 | I9: 1
B11: PA | C11: K | D11: BB | E11: BIP | F11: RBI | G11: H | H11: 1B | I11: 2B | J11: 3B | K11: HR | L11: AVG | M11: OPS
A12: Logan | B12: =SUM(C12:E12,G12) -> 4 | C12: 1 | E12: 1 | G12: =SUM(H12:K12) -> 2 | H12: 2 | L12: =G12/(B12-D12) -> 0.5 | M12: =(D12+G12)/B12 -> 0.5 | N12: =(C12*-1)+D12+(F12*2)+H12+(I12*2)+(J12*3)+(K12*4) -> 1
A13: Stephan | B13: =SUM(C13:E13,G13) -> 4 | D13: 1 | E13: 1 | G13: =SUM(H13:K13) -> 2 | H13: 1 | J13: 1 | L13: =G13/(B13-D13) -> 0.66666667 | M13: =(D13+G13)/B13 -> 0.75 | N13: =(C13*-1)+D13+(F13*2)+H13+(I13*2)+(J13*3)+(K13*4) -> 5
A14: Matt | B14: =SUM(C14:E14,G14) -> 4 | C14: 2 | E14: 2 | G14: =SUM(H14:K14) -> 0 | L14: =G14/(B14-D14) -> 0 | M14: =(D14+G14)/B14 -> 0 | N14: =(C14*-1)+D14+(F14*2)+H14+(I14*2)+(J14*3)+(K14*4) -> -2
A15: Mason | B15: =SUM(C15:E15,G15) -> 2 | C15: 1 | E15: 1 | L15: =G15/(B15-D15) -> 0 | M15: =(D15+G15)/B15 -> 0 | N15: =(C15*-1)+D15+(F15*2)+H15+(I15*2)+(J15*3)+(K15*4) -> -1
A16: Christian | B16: =SUM(C16:E16,G16) -> 6 | C16: 2 | D16: 2 | E16: 1 | G16: =SUM(H16:K16) -> 1 | I16: 1 | L16: =G16/(B16-D16) -> 0.25 | M16: =(D16+G16)/B16 -> 0.5 | N16: =(C16*-1)+D16+(F16*2)+H16+(I16*2)+(J16*3)+(K16*4) -> 2
A17: Liam | B17: =SUM(C17:E17,G17) -> 6 | C17: 1 | D17: 1 | E17: 2 | G17: =SUM(H17:K17) -> 2 | H17: 2 | L17: =G17/(B17-D17) -> 0.4 | M17: =(D17+G17)/B17 -> 0.5 | N17: =(C17*-1)+D17+(F17*2)+H17+(I17*2)+(J17*3)+(K17*4) -> 2
A18: Chuck | B18: =SUM(C18:E18,G18) -> 6 | C18: 1 | E18: 3 | G18: =SUM(H18:K18) -> 2 | H18: 1 | I18: 1 | L18: =G18/(B18-D18) -> 0.33333333 | M18: =(D18+G18)/B18 -> 0.33333333 | N18: =(C18*-1)+D18+(F18*2)+H18+(I18*2)+(J18*3)+(K18*4) -> 2
A19: Jackson | B19: =SUM(C19:E19,G19) -> 1 | E19: 1 | L19: =G19/(B19-D19) -> 0 | M19: =H19/(C19-E19) -> 0 | N19: =(C19*-1)+D19+(F19*2)+H19+(I19*2)+(J19*3)+(K19*4) -> 0

Sheet G7
A1: 44730 | B1: IP | C1: K | D1: BB | E1: RA | F1: HA | G1: 1A | H1: 2A | I1: 3A | J1: HRA | L1: ERA | M1: WHIP
A2: Chuck | B2: 1 | D2: 1 | F2: =SUM(G2:J2) -> 0 | L2: =9*E2/B2 -> 0 | M2: =(D2+F2)/B2 -> 1
A3: Jackson | B3: 1 | D3: 3 | E3: 3 | F3: =SUM(G3:J3) -> 1 | H3: 1 | L3: =9*E3/B3 -> 27 | M3: =(D3+F3)/B3 -> 4
A4: Christian | B4: 1 | D4: 1 | F4: =SUM(G4:J4) -> 0 | L4: =9*E4/B4 -> 0 | M4: =(D4+F4)/B4 -> 1
A5: Liam | B5: 0 | F5: =SUM(G5:J5) -> 0 | L5: =9*E5/B5 -> #DIV/0! | M5: =(D5+F5)/B5 -> #DIV/0!
A6: Matt | B6: 2 | D6: 1 | F6: =SUM(G6:J6) -> 1 | H6: 1 | L6: =9*E6/B6 -> 0 | M6: =(D6+F6)/B6 -> 1
A7: Mason | B7: 1 | E7: 1 | F7: =SUM(G7:J7) -> 2 | H7: 2 | L7: =9*E7/B7 -> 9 | M7: =(D7+F7)/B7 -> 2
A8: Stephan | B8: 1 | C8: 1 | D8: 2 | F8: =SUM(G8:J8) -> 0 | L8: =9*E8/B8 -> 0 | M8: =(D8+F8)/B8 -> 2
A9: Logan
B11: PA | C11: K | D11: BB | E11: BIP | F11: RBI | G11: H | H11: 1B | I11: 2B | J11: 3B | K11: HR | L11: AVG | M11: OPS
A12: Chuck | B12: =SUM(C12:E12,G12) -> 5 | C12: 1 | E12: 4 | G12: =SUM(H12:K12) -> 0 | L12: =G12/(B12-D12) -> 0 | M12: =(D12+G12)/B12 -> 0 | N12: =(C12*-1)+D12+(F12*2)+H12+(I12*2)+(J12*3)+(K12*4) -> -1
A13: Jackson | B13: =SUM(C13:E13,G13) -> 5 | E13: 4 | G13: =SUM(H13:K13) -> 1 | I13: 1 | L13: =G13/(B13-D13) -> 0.2 | M13: =(D13+G13)/B13 -> 0.2 | N13: =(C13*-1)+D13+(F13*2)+H13+(I13*2)+(J13*3)+(K13*4) -> 2
A14: Christian | B14: =SUM(C14:E14,G14) -> 4 | D14: 2 | E14: 1 | G14: =SUM(H14:K14) -> 1 | I14: 1 | L14: =G14/(B14-D14) -> 0.5 | M14: =(D14+G14)/B14 -> 0.75 | N14: =(C14*-1)+D14+(F14*2)+H14+(I14*2)+(J14*3)+(K14*4) -> 4
A15: Liam | B15: =SUM(C15:E15,G15) -> 4 | D15: 1 | E15: 2 | F15: 1 | G15: =SUM(H15:K15) -> 1 | I15: 1 | L15: =G15/(B15-D15) -> 0.33333333 | M15: =(D15+G15)/B15 -> 0.5 | N15: =(C15*-1)+D15+(F15*2)+H15+(I15*2)+(J15*3)+(K15*4) -> 5
A16: Matt | B16: =SUM(C16:E16,G16) -> 7 | C16: 1 | D16: 2 | E16: 4 | F16: 0 | G16: =SUM(H16:K16) -> 0 | I16: 0 | L16: =G16/(B16-D16) -> 0 | M16: =(D16+G16)/B16 -> 0.28571429 | N16: =(C16*-1)+D16+(F16*2)+H16+(I16*2)+(J16*3)+(K16*4) -> 1
A17: Mason | B17: =SUM(C17:E17,G17) -> 7 | C17: 1 | D17: 2 | E17: 3 | F17: 2 | G17: =SUM(H17:K17) -> 1 | I17: 1 | L17: =G17/(B17-D17) -> 0.2 | M17: =(D17+G17)/B17 -> 0.42857143 | N17: =(C17*-1)+D17+(F17*2)+H17+(I17*2)+(J17*3)+(K17*4) -> 7
A18: Stephan | B18: =SUM(C18:E18,G18) -> 6 | D18: 5 | E18: 1 | F18: 1 | G18: =SUM(H18:K18) -> 0 | L18: =G18/(B18-D18) -> 0 | M18: =(D18+G18)/B18 -> 0.83333333 | N18: =(C18*-1)+D18+(F18*2)+H18+(I18*2)+(J18*3)+(K18*4) -> 7
A19: Logan

Sheet G6
A1: 44729 | B1: IP | C1: K | D1: BB | E1: RA | F1: HA | G1: 1A | H1: 2A | I1: 3A | J1: HRA | L1: ERA | M1: WHIP
A2: Jackson | B2: 2 | C2: 2 | D2: 1 | F2: =SUM(G2:J2) -> 2 | G2: 2 | L2: =9*E2/B2 -> 0 | M2: =(D2+F2)/B2 -> 1.5
A3: Stephan | B3: 2 | C3: 1 | D3: 1 | E3: 2 | F3: =SUM(G3:J3) -> 3 | G3: 1 | H3: 2 | L3: =9*E3/B3 -> 9 | M3: =(D3+F3)/B3 -> 2
A4: Mason | B4: 2 | C4: 2 | D4: 3 | F4: =SUM(G4:J4) -> 2 | G4: 1 | H4: 1 | L4: =9*E4/B4 -> 0 | M4: =(D4+F4)/B4 -> 2.5
A5: Matt | B5: 3 | C5: 3 | F5: =SUM(G5:J5) -> 1 | H5: 1 | L5: =9*E5/B5 -> 0 | M5: =(D5+F5)/B5 -> 0.33333333
A6: Chuck | B6: 3 | C6: 4 | D6: 6 | E6: 2 | F6: =SUM(G6:J6) -> 0 | L6: =9*E6/B6 -> 6 | M6: =(D6+F6)/B6 -> 2
A7: Liam
A8: Christian
A9: Logan
B11: PA | C11: K | D11: BB | E11: BIP | F11: RBI | G11: H | H11: 1B | I11: 2B | J11: 3B | K11: HR | L11: AVG | M11: OPS
A12: Jackson | B12: =SUM(C12:E12,G12) -> 7 | C12: 3 | D12: 2 | E12: 1 | F12: 1 | G12: =SUM(H12:K12) -> 1 | H12: 1 | L12: =G12/(B12-D12) -> 0.2 | M12: =(D12+G12)/B12 -> 0.42857143 | N12: =(C12*-1)+D12+(F12*2)+H12+(I12*2)+(J12*3)+(K12*4) -> 2
A13: Stephan | B13: =SUM(C13:E13,G13) -> 6 | D13: 3 | E13: 2 | F13: 1 | G13: =SUM(H13:K13) -> 1 | I13: 1 | L13: =G13/(B13-D13) -> 0.33333333 | M13: =(D13+G13)/B13 -> 0.66666667 | N13: =(C13*-1)+D13+(F13*2)+H13+(I13*2)+(J13*3)+(K13*4) -> 7
A14: Mason | B14: =SUM(C14:E14,G14) -> 6 | C14: 4 | D14: 1 | E14: 1 | G14: =SUM(H14:K14) -> 0 | L14: =G14/(B14-D14) -> 0 | M14: =(D14+G14)/B14 -> 0.16666667 | N14: =(C14*-1)+D14+(F14*2)+H14+(I14*2)+(J14*3)+(K14*4) -> -3
A15: Matt | B15: =SUM(C15:E15,G15) -> 12 | C15: 3 | D15: 3 | E15: 2 | F15: 2 | G15: =SUM(H15:K15) -> 4 | H15: 2 | I15: 2 | L15: =G15/(B15-D15) -> 0.44444444 | M15: =(D15+G15)/B15 -> 0.58333333 | N15: =(C15*-1)+D15+(F15*2)+H15+(I15*2)+(J15*3)+(K15*4) -> 10
A16: Chuck | B16: =SUM(C16:E16,G16) -> 12 | C16: 2 | D16: 2 | E16: 3 | G16: =SUM(H16:K16) -> 5 | H16: 3 | I16: 2 | L16: =G16/(B16-D16) -> 0.5 | M16: =(D16+G16)/B16 -> 0.58333333 | N16: =(C16*-1)+D16+(F16*2)+H16+(I16*2)+(J16*3)+(K16*4) -> 7
A17: Liam
A18: Christian
A19: Logan

Sheet G5
A1: 44728 | B1: IP | C1: K | D1: BB | E1: RA | F1: HA | G1: 1A | H1: 2A | I1: 3A | J1: HRA | L1: ERA | M1: WHIP
A2: Stephan | B2: 2 | C2: 2 | D2: 1 | F2: =sum(G2:J2) -> 1 | H2: 1 | L2: =9*E2/B2 -> 0 | M2: =(D2+F2)/B2 -> 1
A3: Chuck | B3: 2 | C3: 3 | F3: =sum(G3:J3) -> 1 | H3: 1 | L3: =9*E3/B3 -> 0 | M3: =(D3+F3)/B3 -> 0.5
A4: Logan | B4: 1 | C4: 2 | D4: 2 | F4: =sum(G4:J4) -> 0 | L4: =9*E4/B4 -> 0 | M4: =(D4+F4)/B4 -> 2
A5: Matt | B5: 3 | C5: 2 | D5: 1 | F5: =sum(G5:J5) -> 1 | H5: 1 | L5: =9*E5/B5 -> 0 | M5: =(D5+F5)/B5 -> 0.66666667
A6: Christian | B6: 3 | C6: 2 | D6: 2 | E6: 1 | F6: =sum(G6:J6) -> 2 | G6: 1 | H6: 1 | L6: =9*E6/B6 -> 3 | M6: =(D6+F6)/B6 -> 1.3333333
A7: Mason
A8: Jackson
A9: Liam
B11: PA | C11: K | D11: BB | E11: BIP | F11: RBI | G11: H | H11: 1B | I11: 2B | J11: 3B | K11: HR | L11: AVG | M11: OPS
A12: Chuck | B12: 6 | C12: 2 | D12: 2 | E12: 1 | G12: =SUM(H12:K12) -> 1 | H12: 1 | L12: =SUM(E12:I12)/(B12-D12) -> 0.75 | M12: =(D12+sum(E12:I12))/B12 -> 0.83333333 | N12: =(C12*-1)+D12+(F12*2)+H12+(I12*2)+(J12*3)+(K12*4) -> 1
A13: Logan | B13: 6 | C13: 3 | D13: 1 | F13: 1 | G13: =SUM(H13:K13) -> 2 | I13: 2 | L13: =SUM(E13:I13)/(B13-D13) -> 1 | M13: =(D13+sum(E13:I13))/B13 -> 1 | N13: =(C13*-1)+D13+(F13*2)+H13+(I13*2)+(J13*3)+(K13*4) -> 4
A14: Stephan | B14: 5 | C14: 3 | E14: 2 | G14: =SUM(H14:K14) -> 0 | L14: =SUM(E14:I14)/(B14-D14) -> 0.4 | M14: =(D14+sum(E14:I14))/B14 -> 0.4 | N14: =(C14*-1)+D14+(F14*2)+H14+(I14*2)+(J14*3)+(K14*4) -> -3
A15: Matt | B15: 8 | C15: 2 | D15: 1 | E15: 3 | G15: =SUM(H15:K15) -> 2 | I15: 2 | L15: =SUM(E15:I15)/(B15-D15) -> 1 | M15: =(D15+sum(E15:I15))/B15 -> 1 | N15: =(C15*-1)+D15+(F15*2)+H15+(I15*2)+(J15*3)+(K15*4) -> 3
A16: Christian | B16: 8 | C16: 5 | D16: 1 | E16: 2 | G16: =SUM(H16:K16) -> 0 | L16: =SUM(E16:I16)/(B16-D16) -> 0.28571429 | M16: =(D16+sum(E16:I16))/B16 -> 0.375 | N16: =(C16*-1)+D16+(F16*2)+H16+(I16*2)+(J16*3)+(K16*4) -> -4
A17: Mason
A18: Jackson
A19: Liam

Sheet G4
A1: 44715 | B1: IP | C1: K | D1: BB | E1: RA | F1: HA | G1: 1A | H1: 2A | I1: 3A | J1: HRA | L1: ERA | M1: WHIP
A2: Stephan | B2: 2 | C2: 1 | D2: 2 | F2: =sum(G2:J2) -> 2 | G2: 1 | H2: 1 | L2: =9*E2/B2 -> 0 | M2: =(D2+F2)/B2 -> 2
A3: Christian | B3: 2 | C3: 4 | E3: 1 | F3: =sum(G3:J3) -> 1 | J3: 1 | L3: =9*E3/B3 -> 4.5 | M3: =(D3+F3)/B3 -> 0.5
A4: Chuck | B4: 2 | C4: 5 | D4: 2 | F4: =sum(G4:J4) -> 0 | L4: =9*E4/B4 -> 0 | M4: =(D4+F4)/B4 -> 1
A5: Mason | B5: 2 | F5: =sum(G5:J5) -> 2 | G5: 1 | H5: 1 | L5: =9*E5/B5 -> 0 | M5: =(D5+F5)/B5 -> 1
A6: Liam | B6: 2 | C6: 3 | D6: 1 | F6: =sum(G6:J6) -> 1 | H6: 1 | L6: =9*E6/B6 -> 0 | M6: =(D6+F6)/B6 -> 1
A7: Matt | B7: 2 | C7: 1 | D7: 4 | E7: 3 | F7: =sum(G7:J7) -> 1 | J7: 1 | L7: =9*E7/B7 -> 13.5 | M7: =(D7+F7)/B7 -> 2.5
A8: Jackson
A9: Logan
B11: PA | C11: K | D11: BB | E11: BIP | F11: RBI | G11: H | H11: 1B | I11: 2B | J11: 3B | K11: HR | L11: AVG | M11: OPS
A12: Stephan | B12: 10 | C12: 2 | D12: 3 | E12: 4 | F12: 3 | G12: =SUM(H12:K12) -> 2 | I12: 1 | K12: 1 | L12: =SUM(E12:H12)/(B12-D12) -> 1.2857143 | M12: =(D12+sum(E12:H12))/B12 -> 1.2 | N12: =(C12*-1)+D12+(F12*2)+H12+(I12*2)+(J12*3)+(K12*4) -> 13
A13: Christian | B13: 10 | C13: 4 | D13: 3 | E13: 3 | G13: =SUM(H13:K13) -> 0 | L13: =SUM(E13:H13)/(B13-D13) -> 0.42857143 | M13: =(D13+sum(E13:H13))/B13 -> 0.6 | N13: =(C13*-1)+D13+(F13*2)+H13+(I13*2)+(J13*3)+(K13*4) -> -1
A14: Chuck | B14: 9 | D14: 2 | E14: 5 | G14: =SUM(H14:K14) -> 2 | H14: 1 | I14: 1 | L14: =SUM(E14:H14)/(B14-D14) -> 1.1428571 | M14: =(D14+sum(E14:H14))/B14 -> 1.1111111 | N14: =(C14*-1)+D14+(F14*2)+H14+(I14*2)+(J14*3)+(K14*4) -> 5
A15: Mason | B15: 9 | C15: 2 | D15: 1 | E15: 5 | G15: =SUM(H15:K15) -> 1 | H15: 1 | L15: =SUM(E15:H15)/(B15-D15) -> 0.875 | M15: =(D15+sum(E15:H15))/B15 -> 0.88888889 | N15: =(C15*-1)+D15+(F15*2)+H15+(I15*2)+(J15*3)+(K15*4) -> 0
A16: Liam | B16: 8 | C16: 3 | D16: 2 | G16: =SUM(H16:K16) -> 1 | I16: 1 | L16: =SUM(E16:H16)/(B16-D16) -> 0.16666667 | M16: =(D16+sum(E16:H16))/B16 -> 0.375 | N16: =(C16*-1)+D16+(F16*2)+H16+(I16*2)+(J16*3)+(K16*4) -> 1
A17: Matt | B17: 8 | C17: 2 | D17: 3 | E17: 3 | F17: 1 | G17: =SUM(H17:K17) -> 1 | K17: 1 | L17: =SUM(E17:H17)/(B17-D17) -> 1 | M17: =(D17+sum(E17:H17))/B17 -> 1 | N17: =(C17*-1)+D17+(F17*2)+H17+(I17*2)+(J17*3)+(K17*4) -> 7
A18: Jackson
A19: Logan

Sheet G3
A1: 44711 | B1: IP | C1: K | D1: BB | E1: RA | F1: HA | G1: 1A | H1: 2A | I1: 3A | J1: HRA | L1: ERA | M1: WHIP
A2: Matt | B2: 2 | C2: 1 | F2: =sum(G2:J2) -> 5 | G2: 5 | L2: =9*E2/B2 -> 0 | M2: =(D2+F2)/B2 -> 2.5
A3: Chuck | B3: 1 | C3: 2 | D3: 2 | F3: =sum(G3:J3) -> 0 | L3: =9*E3/B3 -> 0 | M3: =(D3+F3)/B3 -> 2
A4: Liam | B4: 2 | C4: 1 | E4: 1 | F4: =sum(G4:J4) -> 2 | H4: 2 | L4: =9*E4/B4 -> 4.5 | M4: =(D4+F4)/B4 -> 1
A5: Christian | B5: 2 | C5: 2 | F5: =sum(G5:J5) -> 0 | L5: =9*E5/B5 -> 0 | M5: =(D5+F5)/B5 -> 0
A6: Logan | B6: 1 | C6: 2 | D6: 1 | E6: 2 | F6: =sum(G6:J6) -> 4 | G6: 4 | L6: =9*E6/B6 -> 18 | M6: =(D6+F6)/B6 -> 5
A7: Finn | B7: 2 | D7: 1 | F7: =sum(G7:J7) -> 2 | G7: 1 | H7: 1 | L7: =9*E7/B7 -> 0 | M7: =(D7+F7)/B7 -> 1.5
A8: Mason
A9: Stephan
A10: Jackson
B12: PA | C12: K | D12: BB | E12: BIP | F12: RBI | G12: H | H12: 1B | I12: 2B | J12: 3B | K12: HR | L12: AVG | M12: OPS
A13: Matt | B13: 5 | C13: 1 | D13: 1 | E13: 2 | F13: 1 | G13: =SUM(H13:K13) -> 1 | I13: 1 | L13: =SUM(E13:I13)/(B13-D13) -> 1.25 | M13: =(D13+sum(E13:I13))/B13 -> 1.2 | N13: =(C13*-1)+D13+(F13*2)+H13+(I13*2)+(J13*3)+(K13*4) -> 4
A14: Chuck | B14: 7 | E14: 2 | F14: 1 | G14: =SUM(H14:K14) -> 5 | H14: 5 | L14: =SUM(E14:I14)/(B14-D14) -> 1.8571429 | M14: =(D14+sum(E14:I14))/B14 -> 1.8571429 | N14: =(C14*-1)+D14+(F14*2)+H14+(I14*2)+(J14*3)+(K14*4) -> 7
A15: Liam | B15: 8 | C15: 1 | D15: 1 | E15: 2 | F15: 1 | G15: =SUM(H15:K15) -> 4 | H15: 4 | L15: =SUM(E15:I15)/(B15-D15) -> 1.5714286 | M15: =(D15+sum(E15:I15))/B15 -> 1.5 | N15: =(C15*-1)+D15+(F15*2)+H15+(I15*2)+(J15*3)+(K15*4) -> 6
A16: Christian | B16: 8 | C16: 2 | D16: 1 | E16: 3 | G16: =SUM(H16:K16) -> 2 | H16: 1 | I16: 1 | L16: =SUM(E16:I16)/(B16-D16) -> 1 | M16: =(D16+sum(E16:I16))/B16 -> 1 | N16: =(C16*-1)+D16+(F16*2)+H16+(I16*2)+(J16*3)+(K16*4) -> 2
A17: Logan | B17: 6 | C17: 1 | D17: 1 | E17: 3 | G17: =SUM(H17:K17) -> 1 | I17: 1 | L17: =SUM(E17:I17)/(B17-D17) -> 1 | M17: =(D17+sum(E17:I17))/B17 -> 1 | N17: =(C17*-1)+D17+(F17*2)+H17+(I17*2)+(J17*3)+(K17*4) -> 2
A18: Finn | B18: 5 | C18: 3 | D18: 1 | E18: 1 | G18: =SUM(H18:K18) -> 0 | L18: =SUM(E18:I18)/(B18-D18) -> 0.25 | M18: =(D18+sum(E18:I18))/B18 -> 0.4 | N18: =(C18*-1)+D18+(F18*2)+H18+(I18*2)+(J18*3)+(K18*4) -> -2
A19: Mason
A20: Stephan
A21: Jackson

Sheet G2
A1: 44708 | B1: IP | C1: K | D1: BB | E1: RA | F1: HA | G1: 1A | H1: 2A | I1: 3A | J1: HRA | L1: ERA | M1: WHIP
A2: Chuck | B2: 2 | C2: 3 | F2: =sum(G2:J2) -> 2 | H2: 2 | L2: =9*E2/B2 -> 0 | M2: =(D2+F2)/B2 -> 1
A3: Christian | B3: 1 | C3: 2 | D3: 1 | F3: =sum(G3:J3) -> 2 | G3: 2 | L3: =9*E3/B3 -> 0 | M3: =(D3+F3)/B3 -> 3
A4: Logan | B4: 1 | C4: 3 | F4: =sum(G4:J4) -> 0 | L4: =9*E4/B4 -> 0 | M4: =(D4+F4)/B4 -> 0
A5: Matt | B5: 2 | C5: 3 | F5: =sum(G5:J5) -> 1 | H5: 1 | L5: =9*E5/B5 -> 0 | M5: =(D5+F5)/B5 -> 0.5
A6: Mason
A7: Stephan
A8: Jackson
A9: Liam
B11: PA | C11: K | D11: BB | E11: BIP | F11: RBI | G11: H | H11: 1B | I11: 2B | J11: 3B | K11: HR | L11: AVG | M11: OPS
A12: Chuck | B12: 5 | C12: 3 | E12: 1 | G12: =SUM(H12:K12) -> 1 | I12: 1 | L12: =SUM(E12:I12)/(B12-D12) -> 0.6 | M12: =(D12+sum(E12:I12))/B12 -> 0.6 | N12: =(C12*-1)+D12+(F12*2)+H12+(I12*2)+(J12*3)+(K12*4) -> -1
A13: Christian | B13: 5 | C13: 3 | E13: 2 | G13: =SUM(H13:K13) -> 0 | L13: =SUM(E13:I13)/(B13-D13) -> 0.4 | M13: =(D13+sum(E13:I13))/B13 -> 0.4 | N13: =(C13*-1)+D13+(F13*2)+H13+(I13*2)+(J13*3)+(K13*4) -> -3
A14: Logan | B14: 6 | C14: 2 | E14: 3 | G14: =SUM(H14:K14) -> 1 | H14: 1 | L14: =SUM(E14:I14)/(B14-D14) -> 0.83333333 | M14: =(D14+sum(E14:I14))/B14 -> 0.83333333 | N14: =(C14*-1)+D14+(F14*2)+H14+(I14*2)+(J14*3)+(K14*4) -> -1
A15: Matt | B15: 7 | C15: 2 | D15: 1 | E15: 1 | G15: =SUM(H15:K15) -> 3 | H15: 1 | I15: 2 | L15: =SUM(E15:I15)/(B15-D15) -> 1.1666667 | M15: =(D15+sum(E15:I15))/B15 -> 1.1428571 | N15: =(C15*-1)+D15+(F15*2)+H15+(I15*2)+(J15*3)+(K15*4) -> 4
A16: Mason
A17: Stephan
A18: Jackson
A19: Liam

Sheet G1
A1: 44707 | B1: IP | C1: K | D1: BB | E1: RA | F1: HA | G1: 1A | H1: 2A | I1: 3A | J1: HRA | L1: ERA | M1: WHIP | N1: Fantasy Points
A2: Matt | B2: 2 | C2: 4 | F2: =sum(G2:J2) -> 1 | G2: 1 | L2: =9*E2/B2 -> 0 | M2: =(D2+F2)/B2 -> 0.5 | N2: =(F2*-1)+(E2*-2)+(D2*-1)+C2 -> 3
A3: Chuck | B3: 2 | C3: 2 | F3: =sum(G3:J3) -> 2 | G3: 1 | H3: 1 | L3: =9*E3/B3 -> 0 | M3: =(D3+F3)/B3 -> 1 | N3: =(F3*-1)+(E3*-2)+(D3*-1)+C3 -> 0
A4: Liam | B4: 2 | D4: 1 | E4: 1 | F4: =sum(G4:J4) -> 4 | G4: 1 | H4: 3 | L4: =9*E4/B4 -> 4.5 | M4: =(D4+F4)/B4 -> 2.5 | N4: =(F4*-1)+(E4*-2)+(D4*-1)+C4 -> -7
A5: Mason | B5: 1 | F5: =sum(G5:J5) -> 2 | G5: 1 | H5: 1 | L5: =9*E5/B5 -> 0 | M5: =(D5+F5)/B5 -> 2 | N5: =(F5*-1)+(E5*-2)+(D5*-1)+C5 -> -2
A6: Christian | N6: =(F6*-1)+(E6*-2)+(D6*-1)+C6 -> 0
A7: Logan | N7: =(F7*-1)+(E7*-2)+(D7*-1)+C7 -> 0
A8: Stephan | N8: =(F8*-1)+(E8*-2)+(D8*-1)+C8 -> 0
A9: Jackson | N9: =(F9*-1)+(E9*-2)+(D9*-1)+C9 -> 0
B11: PA | C11: K | D11: BB | E11: BIP | F11: RBI | G11: H | H11: 1B | I11: 2B | J11: 3B | K11: HR | L11: AVG | M11: OPS
A12: Liam | B12: 7 | C12: 2 | E12: 4 | G12: =SUM(H12:K12) -> 2 | H12: 2 | L12: =SUM(E12:H12)/(B12-D12) -> 1.1428571 | M12: =(D12+sum(E12:H12))/B12 -> 1.1428571 | N12: =(C12*-1)+D12+(F12*2)+H12+(I12*2)+(J12*3)+(K12*4) -> 0
A13: Mason | B13: 10 | C13: 1 | E13: 4 | F13: 1 | G13: =SUM(H13:K13) -> 3 | H13: 1 | I13: 2 | L13: =SUM(E13:H13)/(B13-D13) -> 0.9 | M13: =(D13+sum(E13:H13))/B13 -> 0.9 | N13: =(C13*-1)+D13+(F13*2)+H13+(I13*2)+(J13*3)+(K13*4) -> 6
A14: Chuck | B14: 7 | C14: 2 | E14: 4 | G14: =SUM(H14:K14) -> 1 | I14: 1 | L14: =SUM(E14:H14)/(B14-D14) -> 0.71428571 | M14: =(D14+sum(E14:H14))/B14 -> 0.71428571 | N14: =(C14*-1)+D14+(F14*2)+H14+(I14*2)+(J14*3)+(K14*4) -> 0
A15: Matt | B15: 10 | C15: 1 | D15: 1 | E15: 3 | G15: =SUM(H15:K15) -> 2 | H15: 1 | I15: 1 | L15: =SUM(E15:H15)/(B15-D15) -> 0.66666667 | M15: =(D15+sum(E15:H15))/B15 -> 0.7 | N15: =(C15*-1)+D15+(F15*2)+H15+(I15*2)+(J15*3)+(K15*4) -> 3
A16: Christian
A17: Logan
A18: Stephan
A19: Jackson

Sheet Template
B1: IP | C1: K | D1: BB | E1: RA | F1: HA | G1: 1A | H1: 2A | I1: 3A | J1: HRA | L1: ERA | M1: WHIP
A2: NAME | F2: =SUM(G2:J2) -> 0 | L2: =9*E2/B2 -> #DIV/0! | M2: =(D2+F2)/B2 -> #DIV/0!
A3: NAME | F3: =SUM(G3:J3) -> 0 | L3: =9*E3/B3 -> #DIV/0! | M3: =(D3+F3)/B3 -> #DIV/0!
A4: NAME | F4: =SUM(G4:J4) -> 0 | L4: =9*E4/B4 -> #DIV/0! | M4: =(D4+F4)/B4 -> #DIV/0!
A5: NAME | F5: =SUM(G5:J5) -> 0 | L5: =9*E5/B5 -> #DIV/0! | M5: =(D5+F5)/B5 -> #DIV/0!
A6: NAME | F6: =SUM(G6:J6) -> 0 | L6: =9*E6/B6 -> #DIV/0! | M6: =(D6+F6)/B6 -> #DIV/0!
A7: NAME | F7: =SUM(G7:J7) -> 0 | L7: =9*E7/B7 -> #DIV/0! | M7: =(D7+F7)/B7 -> #DIV/0!
A8: NAME | F8: =SUM(G8:J8) -> 0 | L8: =9*E8/B8 -> #DIV/0! | M8: =(D8+F8)/B8 -> #DIV/0!
A9: NAME | F9: =SUM(G9:J9) -> 0 | L9: =9*E9/B9 -> #DIV/0! | M9: =(D9+F9)/B9 -> #DIV/0!
B11: PA | C11: K | D11: BB | E11: BIP | F11: RBI | G11: H | H11: 1B | I11: 2B | J11: 3B | K11: HR | L11: AVG | M11: OPS
A12: NAME | B12: =SUM(C12:E12,G12) -> 0 | G12: =SUM(H12:K12) -> 0 | L12: =G12/(B12-D12) -> #DIV/0! | M12: =(D12+G12)/B12 -> #DIV/0!
A13: NAME | B13: =SUM(C13:E13,G13) -> 0 | G13: =SUM(H13:K13) -> 0 | L13: =G13/(B13-D13) -> #DIV/0! | M13: =(D13+G13)/B13 -> #DIV/0!
A14: NAME | B14: =SUM(C14:E14,G14) -> 0 | G14: =SUM(H14:K14) -> 0 | L14: =G14/(B14-D14) -> #DIV/0! | M14: =(D14+G14)/B14 -> #DIV/0!
A15: NAME | B15: =SUM(C15:E15,G15) -> 0 | G15: =SUM(H15:K15) -> 0 | L15: =G15/(B15-D15) -> #DIV/0! | M15: =(D15+G15)/B15 -> #DIV/0!
A16: NAME | B16: =SUM(C16:E16,G16) -> 0 | G16: =SUM(H16:K16) -> 0 | L16: =G16/(B16-D16) -> #DIV/0! | M16: =(D16+G16)/B16 -> #DIV/0!
A17: NAME | B17: =SUM(C17:E17,G17) -> 0 | G17: =SUM(H17:K17) -> 0 | L17: =G17/(B17-D17) -> #DIV/0! | M17: =(D17+G17)/B17 -> #DIV/0!
A18: NAME | B18: =SUM(C18:E18,G18) -> 0 | G18: =SUM(H18:K18) -> 0 | L18: =G18/(B18-D18) -> #DIV/0! | M18: =(D18+G18)/B18 -> #DIV/0!
A19: NAME | B19: =SUM(C19:E19,G19) -> 0 | G19: =SUM(H19:K19) -> 0 | L19: =G19/(B19-D19) -> #DIV/0! | M19: =(D19+G19)/B19 -> #DIV/0!

Sheet Temp 2.0
A1: PITCHING | B1: IP | C1: K | D1: BB | E1: RA | F1: HA | G1: 1A | H1: 2A | I1: 3A | J1: HRA | L1: ERA | M1: WHIP | N1: 1/2/3/HR A = Hit Allowed
F2: =SUM(G2:J2) -> 0 | L2: =9*E2/B2 -> #DIV/0! | M2: =(D2+F2)/B2 -> #DIV/0!
F3: =SUM(G3:J3) -> 0 | L3: =9*E3/B3 -> #DIV/0! | M3: =(D3+F3)/B3 -> #DIV/0!
F4: =SUM(G4:J4) -> 0 | L4: =9*E4/B4 -> #DIV/0! | M4: =(D4+F4)/B4 -> #DIV/0!
F5: =SUM(G5:J5) -> 0 | L5: =9*E5/B5 -> #DIV/0! | M5: =(D5+F5)/B5 -> #DIV/0!
F6: =SUM(G6:J6) -> 0 | L6: =9*E6/B6 -> #DIV/0! | M6: =(D6+F6)/B6 -> #DIV/0!
F7: =SUM(G7:J7) -> 0 | L7: =9*E7/B7 -> #DIV/0! | M7: =(D7+F7)/B7 -> #DIV/0!
F8: =SUM(G8:J8) -> 0 | L8: =9*E8/B8 -> #DIV/0! | M8: =(D8+F8)/B8 -> #DIV/0!
F9: =SUM(G9:J9) -> 0 | L9: =9*E9/B9 -> #DIV/0! | M9: =(D9+F9)/B9 -> #DIV/0!
A11: BATTING | B11: PA | C11: K | D11: BB | E11: BIP* | F11: RBI | G11: H | H11: 1B | I11: 2B | J11: 3B | K11: HR | L11: AVG | M11: OPS | N11: BIP = Balls in Play
B12: =SUM(C12:E12,G12) -> 0 | G12: =SUM(H12:K12) -> 0 | L12: =G12/(B12-D12) -> #DIV/0! | M12: =(D12+G12)/B12 -> #DIV/0!
B13: =SUM(C13:E13,G13) -> 0 | G13: =SUM(H13:K13) -> 0 | L13: =G13/(B13-D13) -> #DIV/0! | M13: =(D13+G13)/B13 -> #DIV/0!
B14: =SUM(C14:E14,G14) -> 0 | G14: =SUM(H14:K14) -> 0 | L14: =G14/(B14-D14) -> #DIV/0! | M14: =(D14+G14)/B14 -> #DIV/0!
B15: =SUM(C15:E15,G15) -> 0 | G15: =SUM(H15:K15) -> 0 | L15: =G15/(B15-D15) -> #DIV/0! | M15: =(D15+G15)/B15 -> #DIV/0!
B16: =SUM(C16:E16,G16) -> 0 | G16: =SUM(H16:K16) -> 0 | L16: =G16/(B16-D16) -> #DIV/0! | M16: =(D16+G16)/B16 -> #DIV/0!
B17: =SUM(C17:E17,G17) -> 0 | G17: =SUM(H17:K17) -> 0 | L17: =G17/(B17-D17) -> #DIV/0! | M17: =(D17+G17)/B17 -> #DIV/0!
B18: =SUM(C18:E18,G18) -> 0 | G18: =SUM(H18:K18) -> 0 | L18: =G18/(B18-D18) -> #DIV/0! | M18: =(D18+G18)/B18 -> #DIV/0!
B19: =SUM(C19:E19,G19) -> 0 | G19: =SUM(H19:K19) -> 0 | L19: =G19/(B19-D19) -> #DIV/0! | M19: =(D19+G19)/B19 -> #DIV/0!
